Workbook

Sheet PRICING
A1: Updated - 30/03/2026 | F1: Updated - 26/02/2026 | I1: Updated - 25/03/2026 | L1: Updated - 27/02/2026 | O1: Updated - 25/03/2026 | R1: Updated -31/3/2026 | U1: Updated -31/03/2025 | X1: Updated - 31/03/2026 | AA1: Updated -05/03/2026 | AD1: Updated -29/07/2025 | AG1: Updated - 25/02/2026 | AJ1: Updated - 31/05/2023 | AM1: Updated - 31/03/2026 | AP1: Updated - 29/04/2024 | AS1: Updated - 31/03/2026 | AV1: Updated - 25/03/2026 | AY1: Updated - 27/02/2026 | BB1: Updated 27/03/2026 | BE1: Updated -31/10/2024 | BH1: Updated -24/03/2026 | BK1: Updated 31/3/2026 | BN1: Updated - 31/03/2026 | BQ1: Updated - 31/03/2026 | BT1: Updated - 25/02/2026 | BW1: Updated - 23/03/2026 | BZ1: Updated - 31/03/2026 | CC1: Updated - 18/07/2025 | CF1: Updated - 31/03/2026 | CI1: Updated - 31/03/2026 | CL1: Updated - 30/03/2026 | CO1: Updated - 20/03/2026
A2: YEALINK | F2: DNAKE | I2: CALL4TEL | L2: LG | O2: SHELLY | R2: MIKROTIK | U2: ZYXEL | X2: NETOGY | AA2: TP-LINK | AD2: APACHE OPTICS | AG2: VILO | AJ2: CAMBIUM | AM2: BLUETTI | AP2: MIKROCLOUD | AS2: MOTOROLA | AV2: NEAT | AY2: INOGENI | BB2: LOGITECH | BE2: TELRAD | BH2: HUAWEI | BK2: TELTONIKA | BN2: MECOOL | BQ2: MINIX | BT2: ZTE | BW2: H3C | BZ2: Samsung | CC2: H3C Enterprise | CF2: BARK | CI2: WHALE OS | CL2: GoBright | CO2: Videri
A3: Stock Code | B3: Price (excl. VAT) | C3: SAP | D3: MSRP | F3: Stock Code | G3: Price (excl. VAT) | I3: Stock Code | J3: Price (excl. VAT) | L3: Stock Code | M3: Price (excl. VAT) | O3: Stock Code | P3: Price (excl. VAT) | R3: Stock Code | S3: Price (excl. VAT) | U3: Stock Code | V3: Price (excl. VAT) | X3: Stock Code | Y3: Price (excl. VAT) | AA3: Stock Code | AB3: Price (excl. VAT) | AD3: Stock Code | AE3: Price (excl. VAT) | AG3: Stock Code | AH3: Price (excl. VAT) | AJ3: Stock Code | AK3: Price (excl. VAT) | AM3: Stock Code | AN3: Price (excl. VAT) | AP3: Stock Code | AQ3: Price (excl. VAT) | AS3: Stock Code | AT3: Price (excl. VAT) | AV3: Stock Code | AW3: Price (excl. VAT) | AY3: Stock Code | AZ3: Price (excl. VAT) | BB3: Stock Code | BC3: Pice(excl.VAT) | BE3: Stock Code | BF3: Price (excl. VAT) | BH3: Stock Code | BI3: Price (excl. VAT) | BK3: Stock Code | BL3: Price (excl. VAT) | BN3: Stock Code | BO3: Price (excl. VAT) | BQ3: Stock Code | BR3: Price (excl. VAT) | BT3: Stock Code | BU3: Price (excl. VAT) | BW3: Stock Code | BX3: Price (excl. VAT) | BZ3: Stock Code | CA3: Price (excl. VAT) | CC3: Stock Code | CD3: Price (excl. VAT) | CF3: Stock Code | CG3: Price (excl. VAT) | CI3: Stock Code | CJ3: Price (excl. VAT) | CL3: Stock Code | CM3: Price (excl. VAT) | CO3: Stock Code | CP3: Price (excl. VAT)
A4: AMS | B4: P.O.R | F4: 280M-S8 | G4: 515 | I4: NX32 LITE | J4: 5299 | L4: 22SM3G | M4: 6334 | O4: SHELLY DUO CW/WW (E27) | P4: 229 | R4: ACT-NVD | S4: 409 | U4: NWA110AX | V4: 3388.416 | X4: NOVA10 | Y4: 849 | AA4: ARCHER C80 | AB4: 613 | AD4: 1P-SFP1GESX | AE4: 431 | AG4: Vilo-5-3 | AH4: 1299 | AJ4: 1CMXEX1010XXAE | AK4: 5727 | AM4: PV120 | AN4: 2899 | AP4: MC-SDWAN | AQ4: 8 | AS4: MA1 | AT4: 799 | AV4: NEATPAD-SE | AW4: 14181 | AY4: 4KX-PLUS | AZ4: 11385 | BB4: 12X2S00012 | BC4: 27299 | BE4: BreezeAIR AXE-L 5-200-17-PTMP-CPE | BF4: 6469 | BH4: AP362 | BI4: 1843 | BK4: OTD140 | BL4: 2240 | BN4: KD3 | BO4: 799 | BQ4: C1-NS | BR4: 969 | BT4: ZXHN-H3601P | BU4: 525 | BW4: LS-1600V2-6P-HPWR-GL | BX4: 997 | BZ4: 58-QB65C | CA4: 14565 | CC4: TEST | CD4: 999 | CF4: BARK HOME 5100-S | CG4: 1599 | CI4: WHALE OS PROJECTOR | CJ4: 2599 | CL4: GB-ROOM 1-9 | CM4: 3360 | CO4: Spark2 | CP4: 33630
A5: YDMP | B5: P.O.R | F5: 902M-S8 | G5: 675 | I5: NX96(B) | J5: 17499 | L5: 32SM5JB | M5: 7205 | O5: SHELLY VINTAGE A60 (E27) | P5: 229 | R5: 18POW | S5: 105 | U5: NWA210AX | V5: 4271.22 | X5: NOVA10 BLUETOOTH RCU | Y5: 129 | AA5: ARCHER MR200 | AB5: 955 | AD5: 1P-SFP1GELX | AE5: 482 | AJ5: 1CMXEX1010PXAE | AK5: 8040 | AP5: MC-ADV_MON | AQ5: 30 | AS5: SJMC302 | AT5: 199 | AV5: NEATPADPRO10-SE | AW5: 20580 | AY5: 4KXUSB3 | AZ5: 10893 | BB5: 910-003357 | BC5: 89 | BE5: BreezeAIR AXE-L 5-200-23-PTMP-CPE | BF5: 7255 | BH5: AC650-128AP | BI5: 6037 | BK5: RUT140 | BL5: 997 | BN5: KM7 PLUS | BO5: 899 | BQ5: H1-NS | BR5: 969 | BT5: ZXHN-H3601P-INT | BU5: 525 | BW5: LS-1600V2-10P-HPWR-GL | BX5: 1507 | BZ5: 58-QB75C | CA5: 24999 | CL5: GB-ROOM 10-24 | CM5: 3150 | CO5: SparkQ+ | CP5: 43985
A6: SIP-T30 | B6: 642 | C6: N/A | D6: N/A | F6: 904M-S3 | G6: 833 | I6: NX256 | J6: 44999 | L6: 43UH5QE | M6: 10168 | O6: SHELLY VINTAGE G125 (E27) | P6: 359 | R6: 24HPOW | S6: 256 | U6: WX3100-T0 | V6: 629 | X6: NOVA PRO BLUETOOTH RCU | Y6: 129 | AA6: ARCHER MR600 V5 | AB6: 1538 | AD6: 1P-SFP1GET | AE6: 1147 | AJ6: 1CMXEX1028XXAE | AK6: 10342 | AP6: MC-SEC_ESS | AQ6: 59 | AS6: SJMC502 | AT6: 349 | AV6: NEATPAD-GLASSMOUNT | AW6: 1020 | AY6: 4K2USB3 | AZ6: 7780 | BB6: 910-006221 | BC6: 789 | BE6: BreezeAIR AXE-L 5-500-17-PTMP-CPE | BF6: 7299 | BH6: S310-24P4S | BI6: 5737 | BK6: RUT142 | BL6: 1109 | BN6: V02 | BO6: 129 | BQ6: CP86-CP-NS | BR6: 769 | BT6: G5TS | BU6: 1650 | BW6: LS-1600V2-18P-HPWR-GL | BX6: 3194 | BZ6: 58-QB85C | CA6: 33152 | CL6: GB-ROOM 25-49 | CM6: 2940 | CO6: Spark3 | CP6: 31040
A7: PSU-12V/1A | B7: 148 | C7: N/A | D7: N/A | F7: 905D-Y4 | G7: 2795 | L7: 49UH5NM | M7: 12317 | O7: SHELLY TEMP SENSOR (DS18B20) | P7: 74.510909 | R7: 48POW | S7: 249 | U7: GS1008-HP | V7: 1371.72 | X7: YCABLE | Y7: 59 | AA7: CPE210 | AB7: 429 | AD7: 1P-SFP10GSR | AE7: 1017 | AJ7: 1CMXEX1028PXAE | AK7: 15200 | AP7: MC-WEB_CON | AQ7: 74 | AS7: SJMC682 | AT7: 399 | AV7: NEATBOARDPRO-SE | AW7: 140636 | AY7: HD2USB3 | AZ7: 6306 | BB7: 910-006274 | BC7: 509 | BE7: BreezeAIR AXE-L 5-500-23-PTMP-CPE | BF7: 7998 | BH7: S380-L4P1T | BI7: 2788 | BK7: RUT361 | BL7: 3694 | BN7: KS3 | BO7: 5999 | BQ7: CP89-HD-NS | BR7: 3799 | BW7: LS-1600V2-26P-HPWR-GL | BX7: 4494 | BZ7: 58-QM50C | CA7: 10653 | CL7: GB-ROOM 50+ | CM7: 2730 | CO7: Spark4 | CP7: 36219
A8: COM-W73P/H-CHRG | B8: 49 | C8: N/A | D8: N/A | L8: 55UH5Q-E | M8: 13250 | O8: SHELLY BYPASS | P8: 53.865974 | R8: ACRPSMA | S8: 128 | U8: GS1200-5HPv2 | V8: 1269.768 | X8: UPS100-PLUS | Y8: 599 | AA8: CPE220 | AB8: 600 | AD8: 1P-SFP10GLR | AE8: 1448 | AJ8: 1CMXEX2010xxA0 | AK8: 10270 | AP8: MC-WAN-F/O | AQ8: 74 | AV8: NEATBOARDPRO-ADAPTIVE-STAND | AW8: 61559 | AY8: HD2USB3UP | AZ8: 1440 | BB8: 910-006275 | BC8: 489 | BE8: BreezeAirAXE-5-1G-17-PTMP-CPE | BF8: 8125 | BH8: S380-S8P2T | BI8: 4468 | BK8: RUT200 | BL8: 1575 | BN8: GM1 | BO8: 599 | BQ8: CP86-AA-NS | BR8: 769 | BW8: LS-1600V2-26S-HPWR-GL | BX8: 4672 | BZ8: 58-QM55C | CA8: 13586 | CL8: GB-ROOMSIG 1-9 | CM8: 2520 | CO8: Spark5 | CP8: 38809
A9: COM-W59R-CHRG | B9: 122 | C9: N/A | D9: N/A | L9: 65UL3Q-E | M9: 16676 | O9: SHELLY 50A CLAMP | P9: 252.44364 | R9: C52IG-5HAXD2HAXD-TC | S9: 1431 | U9: GS1200-8HPv2 | V9: 1458.768 | X9: NOVA PRO | Y9: 1099 | AA9: CPE510 | AB9: 695 | AD9: 1P-SFP10GUTP | AE9: 2954 | AJ9: 1CMXEX2010PxA0 | AK9: 14420 | AP9: MC-STATIC | AQ9: 129 | AV9: NEATBOARDPRO-ADAPTIVE-MOUNT | AW9: 26765 | AY9: SDI2USB3 | AZ9: 8927 | BB9: 910-006348 | BC9: 489 | BE9: BreezeAirAXE-5-1G-23-PTMP-CPE | BF9: 8738.9957 | BH9: S380-H8T3ST | BI9: 6406 | BK9: RUT260 | BL9: 3067 | BN9: G20 | BO9: 199 | BW9: LS-1850V2-10P-HPWR-EI-GL | BX9: 2540 | BZ9: 58-QM65C | CA9: 16847 | CL9: GB-ROOMSIG 10-24 | CM9: 2363
A10: COM-W56P/H-CHRG | B10: 65 | C10: N/A | D10: N/A | L10: 65UH5Q-E | M10: 16676 | O10: SHELLY 120A CLAMP | P10: 340.78815 | R10: CAPGI-5HAXD2HAXD | S10: 1922 | U10: GS1900-8HP | V10: 1951.728 | X10: AIRNOVA | Y10: 799 | AA10: CPE610 | AB10: 929 | AD10: 1P-SFP25GSR | AE10: 1630 | AJ10: 1CMXEX2028xxA0 | AK10: 18569 | AP10: MC-VPN-ACC | AQ10: 130 | AV10: NEATBOARDPRO-WALLMOUNT | AW10: 7206 | AY10: TOGGLE | AZ10: 8108 | BB10: 910-006438 | BC10: 739 | BE10: BreezeAirAXE-5-2G-PTMP | BF10: 29475 | BH10: AR730 | BI10: 15398 | BK10: RUT901 | BL10: 2393 | BW10: LS-1850V2-28P-HPWR-EI-GL | BX10: 5398 | BZ10: 58-QM75C | CA10: 33695 | CL10: GB-ROOM 25-49 | CM10: 2205
A11: COM-W56P/H-BACK-COVER | B11: 20 | C11: N/A | D11: N/A | L11: 75UH5N-M | M11: 32608 | O11: SHELLY PLUS ADD-ON | P11: 271.32435 | R11: CCR2004-16G-2S+ | S11: 6942 | U11: GS1900-10HP | V11: 2592.7625 | X11: AIRNOVAMAX | Y11: 1199 | AA11: CPE710 | AB11: 1074 | AD11: 1P-SFP25GLR | AE11: 2547 | AJ11: 1CMXEX2028PxA0 | AK11: 26869 | AP11: MC-VPN-USER | AQ11: 26 | AV11: NEATBOARD32-SE | AW11: 71163 | AY11: TOGGLE ROOMS | AZ11: 18755 | BB11: 910-006494 | BC11: 1039 | BE11: BreezeAirAXE-5-1G-PTMP | BF11: 25025 | BH11: AR720 | BI11: 7350 | BK11: RUT906 | BL11: 2530 | BW11: LS-1850V2-52X-PWR-GL | BX11: 13689 | BZ11: 58-QM85C | CA11: 41303 | CL11: GB-ROOMSIG 50+ | CM11: 2048
A12: COM-W56H-BC | B12: 25 | C12: N/A | D12: N/A | L12: 86UL5Q-E | M12: 40790 | O12: SHELLY PLUS SMOKE ALARM | P12: 841.26098 | R12: CCR2004-16G-2S+PC | S12: 6788 | U12: GS1900-24HPv2 | V12: 6349.6224 | AA12: DECO E4-1 | AB12: 408 | AD12: 1P-SFP25GER | AE12: 10700 | AJ12: 1CMXEX2052GxxA00 | AK12: 31019 | AP12: MC-MIK-RENTAL | AQ12: 135 | AV12: NB32-TBLST | AW12: 7206 | AY12: U-BRIDGE | AZ12: 6306 | BB12: 910-006496 | BC12: 999 | BE12: FLAT-PANEL-ANT-5G-90 | BF12: 8145 | BH12: S110-8P2ST | BI12: 733 | BK12: RUT951 | BL12: 3648 | BW12: LS-5120V3-28P-PWR-LI-GL | BX12: 5530 | CL12: GB-CATSERVL | CM12: 1106
A13: COM-T7-WMB | B13: 60 | C13: N/A | D13: N/A | L13: 98UM5K | M13: 89483 | O13: SHELLY PRO 2PM | P13: 1566.7834 | R13: CCR2004-1G-12S+2XS | S13: 8864 | U13: GS1920-8HPv2 | V13: 4233.0816 | AA13: DECO E4-2 | AB13: 784 | AD13: 1P-SFP25GZR | AE13: 101909 | AJ13: 1CMXEX2052GxPA00 | AK13: 43468 | AP13: VG10 | AQ13: 432 | AV13: NB32-WALL-MNT | AW13: 5147 | AY13: U-BRIDGE3 | AZ13: 13227 | BB13: 910-006582 | BC13: 1899 | BE13: DISH-ANT-5G-5 | BF13: 7325 | BH13: S110-16LP2SR | BI13: 2951 | BK13: RUT956 | BL13: 4156 | BW13: LS-5120V3-28P-HPWR-LI-GL | BX13: 6199 | CL13: GB-DESK 1-249 | CM13: 448
A14: COM-T56/T58-HS | B14: 75 | C14: N/A | D14: N/A | L14: 98UH5J-H | M14: 114130 | O14: SHELLY PRO 3EM-120A | P14: 2254.0553 | R14: CCR2116-12G-4S+ | S14: 15209 | U14: GS1920-24HPv2 | V14: 8115.06 | AA14: DECO E4-3 | AB14: 1160 | AD14: 1P-QSFP40GSR | AE14: 2038 | AJ14: 1CMXEX2052GxPA10 | AK14: 37243 | AP14: VG25 | AQ14: 972 | AV14: NB32-AD-TBLST | AW14: 16265 | AY14: U-CAM | AZ14: 9746 | BB14: 910-006958 | BC14: 1359 | BE14: DISH-ANT-5G-3-5 | BF14: 8775 | BH14: S110-24LP2SR | BI14: 4250 | BK14: RUTX10 | BL14: 3233 | BW14: LS-5120V3-52P-PWR-LI-GL | BX14: 11502 | CL14: GB-DESK 250-999 | CM14: 420
A15: COM-T48 WMB | B15: 60 | C15: N/A | D15: N/A | L15: 110UM5K | M15: 209783 | O15: SHELLY PRO 3EM-400A | P15: 4447.517 | R15: CCR2216-1G-12XS-2XQ | S15: 37307 | U15: GS1920-48HPv2 | V15: 11218.008 | AA15: DECO M4-1 | AB15: 545 | AD15: 1P-QSFP40GLR | AE15: 8152 | AJ15: 1CPLE410X00BRW | AK15: 4835 | AP15: VG50 | AQ15: 1620 | AV15: NB32-AD-TBLST-B | AW15: 5015 | AY15: CAM230 | AZ15: 15970 | BB15: 910-006959 | BC15: 1319 | BE15: DISH-ANT-5G-3 | BF15: 20525 | BH15: S220-24T4X | BI15: 4474 | BK15: RUTX11 | BL15: 5726 | BW15: LS-5120V3-28S-PWR-LI-GL | BX15: 7722 | CL15: GB-DESK 1000-1999 | CM15: 392
A16: COM-T46G/T46U/T48G/T48U HS | B16: 98 | C16: N/A | D16: N/A | L16: 55TR3DQ | M16: 24999 | O16: SHELLY PRO 4PM | P16: 1856.7965 | R16: CRS112-8P-4S-IN | S16: 3182 | U16: USGFLEX100-D | V16: 8756.923 | AA16: DECO M4-2 | AB16: 1023 | AD16: 1P-QSFP40GER | AE16: 32101 | AJ16: 1CPLE510X00ARW | AK16: 9706 | AP16: VG100 | AQ16: 2160 | AV16: NB32-AD-TBLCL | AW16: 16265 | AY16: SHARE2U | AZ16: 34316 | BB16: 910-007182 | BC16: 269 | BE16: BREEZEAIR-AXE | BF16: 10999 | BH16: S220-24P4X | BI16: 5333 | BK16: RUTX12 | BL16: 8265 | BW16: LS-5120V3-28S-HPWR-LI-GL | BX16: 9865 | CL16: GB-DESK 2000+ | CM16: 364
A17: COM-T46 WMB | B17: 60 | C17: N/A | D17: N/A | L17: 65TR3DQ | M17: 28260 | O17: SHELLY PRO 1PM | P17: 1177.0088 | R17: CRS305-1G-4S+IN | S17: 2287 | U17: USGFLEX200-D | V17: 12434.677 | AA17: DECO M4-3 | AB17: 1501 | AD17: 1P-QSFP40GZR | AE17: 91718 | AJ17: 1CPLE600X00ARW | AK17: 7987 | AP17: VG150 | AQ17: 3240 | AV17: NB32-AD-TBLCL-B | AW17: 5015 | AY17: SHARE2 | AZ17: 26126 | BB17: 910-007511 | BC17: 449 | BE17: BREEZEAIR-AXE-CON | BF17: 9499 | BH17: S220-48T4X | BI17: 7891 | BK17: RUTX14 | BL17: 6649 | BW17: LS-5120V3-28F-LI-GL | BX17: 6175 | CL17: GB-PARKING 1-249 | CM17: 448
A18: COM-T40/T41/T42 WMB | B18: 59 | C18: N/A | D18: N/A | L18: 75TR3DQ | M18: 32608 | O18: SHELLY BLU BUTTON1 (BLUE) | P18: 299 | R18: CRS309-1G-8S+IN | S18: 4058 | U18: NWA50AX | V18: 1656.996 | AA18: DECO M5-3 | AB18: 2252 | AD18: 1P-QSFP100GSR | AE18: 2751 | AJ18: 1CPLE700X00ARW | AK18: 16631 | AP18: VG250 | AQ18: 4320 | AV18: NB32-AD-TBL-BLT | AW18: 5015 | AY18: CAM300 | AZ18: 29402 | BB18: 920-002479 | BC18: 229 | BH18: S220-48T4S | BI18: 5688 | BK18: RUTX50 | BL18: 8270 | BW18: LS-6520X-16ST-SI-GL | BX18: 15855 | CL18: GB-PARKING 250-999 | CM18: 420
A19: COM-T3X HST | B19: 88 | C19: N/A | D19: N/A | L19: 86TR3DQ | M19: 38042 | O19: SHELLY BLU BUTTON1 (RED) | P19: 299 | R19: CRS310-1G-5S-4S+IN | S19: 2966 | U19: IES5206M-ZZ01V1F | V19: P.O.R | AA19: DECO X10-2P | AB19: 1364 | AD19: 1P-QSFP100GLR | AE19: 12025 | AJ19: 1CXV22X00A00RW | AK19: 8892 | AP19: VG500 | AQ19: 8640 | AV19: NB32-PRIV | AW19: 2594 | BB19: 920-004509 | BC19: 379 | BH19: S220-48P4X | BI19: 9471 | BK19: RUTM10 | BL19: 2217 | BW19: PSR75-12A-GL | BX19: 1102 | CL19: GB-PARKING 1000-1999 | CM19: 392
A20: COM-T33G-WMB | B20: 60 | C20: N/A | D20: N/A | L20: 75UR640S | M20: 18477.174 | O20: SHELLY BLU BUTTON1 (BLACK) | P20: 299 | R20: CRS310-1G-5S-4S+OUT | S20: 3655 | U20: IES5206M-ZZ01V2F | V20: P.O.R | AA20: DECO X20-2 | AB20: 1706 | AD20: 1P-QSFP100GER | AE20: 47387 | AJ20: 1CXV221X0A00RW | AK20: 5965 | AP20: VG1000 | AQ20: 12960 | AV20: NB32-CBL-LOCK | AW20: 2594 | BB20: 920-009204 | BC20: 879 | BH20: S220-48P4S | BI20: 8462 | BK20: TAP200 | BL20: 1011 | BW20: EWP-WA6020 | BX20: 1098 | CL20: GB-PARKING 2000+ | CM20: 364
A21: COM-T29G-WMB | B21: 58 | C21: N/A | D21: N/A | O21: SHELLY 1 MINI GEN3 | P21: 253.12684 | R21: CRS312-4C+8XG-RM | S21: 10552 | U21: IES5212M-ZZ01V1F | V21: P.O.R | AA21: DECO X20-3 | AB21: 2525 | AD21: 1P-QSFP100GZR | AE21: 81527 | AJ21: 1CXV222H0A00RW | AK21: 6976 | AV21: NEATBOARD50-SE | AW21: 112471 | BB21: 920-010251 | BC21: 2059 | BH21: S310-24T4X | BI21: 4663 | BK21: TRB140 | BL21: 2122 | BW21: EWP-WA6022H | BX21: 966 | CL21: GB-MAP 1-9 | CM21: 6286
A22: COM-SC | B22: 25 | C22: N/A | D22: N/A | O22: SHELLY 1PM MINI GEN3 | P22: 287.05733 | R22: CRS317-1G-16S+RM | S22: 7917 | U22: OLT1404A-ZZ01V1F | V22: P.O.R | AA22: DECO X55-1 | AB22: 955 | AD22: 1P-BU1310155010KM | AE22: 560 | AJ22: 1CXV22T0XA00RW | AK22: 13106 | AV22: NEATBOARD50-WALLMOUNT | AW22: 6382 | BB22: 920-010352 | BC22: 2239 | BH22: S310-24P4X | BI22: 6628 | BK22: TRB142 | BL22: 1894 | BW22: EWP-WA6120 | BX22: 1375 | CL22: GP-MAP 10-24 | CM22: 5893
A23: COM-EAR-CUSHION-BH72-5PR | B23: 1004 | C23: N/A | D23: N/A | O23: SHELLY BLU GATEWAY | P23: 272.69355 | R23: CRS318-16P-2S+OUT | S23: 4165 | U23: OLT1408A-ZZ01V1F | V23: P.O.R | AA23: DECO X55-2 | AB23: 1842 | AD23: 1P-BD1550131010KM | AE23: 662 | AJ23: 1CXV22T1XA00RW | AK23: 15076 | AV23: NEATBOARD50-ADAPTIVESTAND | AW23: 40970 | BB23: 920-010608 | BC23: 1859 | BH23: S310-48T4X | BI23: 10814 | BK23: TRB143 | BL23: 3065 | BW23: EWP-WA6126 | BX23: 3162 | CL23: GB-MAP 25-49 | CM23: 5500
A24: COM-EAR-CUSHION-BH72-1PR | B24: 200 | C24: N/A | D24: N/A | O24: SHELLY BLU MOTION | P24: 370.88636 | R24: CRS318-1FI-15FR-2S-OUT | S24: 2435 | U24: OLT2406-ZZ01V1F | V24: P.O.R | AA24: DECO XE75(3-PACK) | AB24: 4437 | AJ24: 1CXV38X00A00RW | AK24: 24281 | AV24: NEATBOARD50-ADAPTIVEMOUNT | AW24: 24706 | BB24: 920-010933 | BC24: 3539 | BH24: S310-48P4X | BI24: 10072 | BK24: TRB145 | BL24: 1894 | BW24: EWP-WA6120H | BX24: 1881 | CL24: GB-MAP 50+ | CM24: 5107
A25: CAM50 | B25: 1149 | C25: 1775.1 | D25: 2013 | O25: SHELLY BLU BUTTON TOUGH 1 BLAC | P25: 331.24826 | R25: CRS326-24G-2S+RM | S25: 3239 | U25: ALM2406 | V25: P.O.R | AA25: EAP110 | AB25: 442 | AJ25: 1CXE34X00A06RW | AK25: 15081 | AV25: NEATBAR-BYOD | AW25: 11805 | BB25: 920-011004 | BC25: 1319 | BH25: S310-48P4S | BI25: 10505 | BK25: TRB246 | BL25: 2425 | BW25: EWP-WA6120X | BX25: 3506 | CL25: GB-VISITL | CM25: 17500
A26: COM-W52P/H-BC | B26: 15 | C26: N/A | D26: N/A | O26: SHELLY BLU H&T (BLACK) | P26: 340.93091 | R26: CRS326-24S+2Q+RM | S26: 8901 | U26: OFC2406 | V26: P.O.R | AA26: EAP115 | AB26: 378 | AJ26: 1CXE58X00A00RW | AK26: 36987 | AV26: NEATBAR2-SE | AW26: 59521 | BB26: 920-011032 | BC26: 1279 | BH26: AP361 | BI26: 791 | BK26: TSW010 | BL26: 501 | BW26: EWP-WSG1812X-PWR | BX26: 6087 | CL26: GB-VIEW-CORE 1-9 | CM26: 3486
A27: UH36-MONO-USBC | B27: 669 | C27: N/A | D27: N/A | O27: SHELLY PLUS UNI | P27: 281.79394 | R27: CRS328-24P-4S+RM | S27: 7419 | U27: OPA2406 | V27: P.O.R | AA27: EAP115-WALL | AB27: 347 | AV27: NEATBAR2-BE | AW27: 59521 | BB27: 920-012077 | BC27: 699 | BH27: AP160 | BI27: 975 | BK27: TSW100 | BL27: 1434 | BW27: EWP-WSG1840X | BX27: 6135 | CL27: GB-VIEW-CORE 10-24 | CM27: 3268
A28: CP965-TEAMS | B28: 9112 | C28: 13017 | D28: 15642 | O28: SHELLY PM MINI GEN3 | P28: 273.47074 | R28: CRS328-4C-20S-4S+RM | S28: 6354 | U28: MSC1240XA-ZZ01V1F | V28: P.O.R | AA28: EAP225 | AB28: 821 | AV28: NEATBARPRO-SE | AW28: 94445 | BB28: 920-012334 | BC28: 1029 | BH28: AP761 | BI28: 3099 | BK28: TSW101 | BL28: 1230 | BW28: NS-SecPath F100-C-A1-I | BX28: 4741 | CL28: GB-VIEW-CORE 25-49 | CM28: 3050
A29: MP52 E2 | B29: 2199 | C29: 4110 | D29: 3984 | O29: SHELLY BLU DOOR WINDOW BLACK | P29: 310.11188 | R29: CRS354-48G-4S+2Q+RM | S29: 9163 | U29: MSC1280XA-ZZ01V1F | V29: P.O.R | AA29: EAP225-OUTDOOR | AB29: 821 | AV29: NEATFRAME-SE | AW29: 10359 | BB29: 920-012508 | BC29: 1629 | BH29: AP371 | BI29: 1390 | BK29: TSW200 | BL29: 1669 | BW29: RT-MSR610 | BX29: 2246 | CL29: GB-VIEW-CORE 50+ | CM29: 2832
A30: MP54 E2 | B30: 3596 | C30: 5138 | D30: 5028 | O30: SHELLY BLU DOOR WINDOW WHITE | P30: 323.41527 | R30: CRS354-48P-4S+2Q+RM | S30: 14784 | U30: OLC3416-42A-ZZ01V1F | V30: P.O.R | AA30: EAP245 | AB30: 1074 | AV30: NEATCENTER-SE | AW30: 39604 | BB30: 920-013333 | BC30: 879 | BH30: S220-8T4S | BI30: 1756 | BK30: TSW202 | BL30: 2194 | BW30: SFP-GE-SX-MM850-A | BX30: 1681 | CL30: GB-VIEW-PREMIUM 1-9 | CM30: 658
A31: MP55 E2 | B31: 3788 | C31: 5412 | D31: 5550 | O31: SHELLY BLU RC BUTTON 4 | P31: 292.01711 | R31: CRS504-4XQ-IN | S31: 12916 | U31: GLC1440X-55-ZZ01V1F | V31: P.O.R | AA31: EAP610 | AB31: 1137 | AV31: POE-INJ-NEATCENTER | AW31: 1556 | BB31: 920-013349 | BC31: 1239 | BH31: S220-8P4S | BI31: 2644 | BK31: TSW212 | BL31: 1894 | BW31: SFP-GE-LX-SM1310-A | BX31: 3738 | CL31: GB-VIEW-PREMIUM 10-24 | CM31: 617
A32: MP56 E2 | B32: 4556 | C32: 6508 | D32: 6246 | O32: SHELLY WALL DISPLAY + BLU H&T | P32: 2472.906 | R32: CRS510-8XS-2XQ-IN | S32: 14931 | U32: GLC1440X-55A-ZZ01V1F | V32: P.O.R | AA32: EAP610-OUTDOOR | AB32: 1770 | AV32: NEATPAD-HEX8-4 | AW32: 156 | BB32: 939-001487 | BC32: 2779 | BH32: AR303 | BI32: 1486 | BK32: PR1ICC60 | BL32: 2540 | BW32: SFP-XG-SX-MM850-E | BX32: 814 | CL32: GB-VIEW-PREMIUM 25-49 | CM32: 575
A33: MP58-WH E2 | B33: 5515 | C33: 7878 | D33: 8334 | O33: SHELLY WALL DISPLAY+BLU H&T(W) | P33: 2571.3964 | R33: CRS518-16XS-2XQ-RM | S33: 25857 | U33: OMU2442-ZZ01V1F | V33: P.O.R | AA33: EAP615-WALL | AB33: 884 | AV33: NEATPAD-WALLADAPT | AW33: 502 | BB33: 939-001490 | BC33: 3719 | BH33: S530-48S4XE | BI33: 11809 | BK33: RUTM11 | BL33: 4895 | BW33: SFP-XG-LX-SM1310 | BX33: 1481 | CL33: GB-VIEW-PREMIUM 50+ | CM33: 535
A34: AX83H | B34: 1693 | C34: 2419 | D34: 2766 | O34: SHELLY TEMP SENSOR DS18B20 3M | P34: 137.34611 | R34: CSS326-24G-2S+RM | S34: 2413 | U34: OLC2404-22-ZZ01V2F | V34: P.O.R | AA34: EAP620 HD | AB34: 1580 | AV34: NEATPAD-SIDEMOUNT | AW34: 597 | BB34: 939-001498 | BC34: 1719 | BH34: S530-24ST4XE | BI34: 8124 | BK34: RUT241-eSIM | BL34: 2702 | BW34: EWPAM1HPOE-GL | BX34: 343 | CL34: GB-WEEKPLANNER | CM34: 9086
A35: AX86R | B35: 2469 | C35: 3528 | D35: 3810 | O35: SHELLY H&T GEN3 (BLACK) | P35: 622.21972 | R35: CSS610-1GI-7R-2S+OUT | S35: 2114 | U35: EX3301-T0 | V35: 799 | AA35: EAP650 | AB35: 1264 | AV35: NEATPAD-WALLBRACK | AW35: 674 | BB35: 939-001644 | BC35: 4579 | BH35: S530-24T4XE | BI35: 6773 | BK35: PR313EU3 | BL35: 1142 | BW35: SOHO-SWITCH-FL-02 | BX35: 26 | CL35: GB-WAYFINDERL | CM35: 5586
A36: COM-BTH58 | B36: 564 | C36: 806 | D36: 870 | O36: SHELLY PRO EM - 50 | P36: 1442.0024 | R36: CSS610-8P-2S+IN | S36: 3396 | U36: EX5301-B3 | V36: 1749 | AA36: EAP660 HD | AB36: 2971 | AV36: BARPRO-MOUNT-ADAPTER | AW36: 1626 | BB36: 939-001647 | BC36: 5169 | BH36: USG6000E-S03 | BI36: 0 | BK36: PR1KCL25 | BL36: 194 | BW36: RTU-FL-F | BX36: 56 | CL36: GB-LOCKERBANK | CM36: 6286
A37: CP925 | B37: 5174 | C37: 7392 | D37: 10422 | O37: SHELLY DIMMER 0/1-10V GEN3 | P37: 320.52106 | R37: D53G-5HACD2HND-TC&RG520F-EU | S37: 7278 | U37: GS1915-24E | V37: 2699 | AA37: EAP670 | AB37: 1833 | AV37: BARPRO-SCREENMOUNT-HORIZONTALBAR | AW37: 1193 | BB37: 939-001656 | BC37: 2849 | BH37: USG6000E-S13 | BI37: 18678 | BK37: SWM282 | BL37: 5667 | BW37: LS-1850V2-10P-EI-GL | BX37: 1683 | CL37: GB-API-ACCESS | CM37: 16786
A38: CP935W | B38: 7762 | C38: 11089 | D38: 13902 | O38: SHELLY DIMMER GEN3 | P38: 691.26849 | R38: E50UG | S38: 831 | U38: GS1915-24EP | V38: 5363.9578 | AA38: EC220-G5 | AB38: 358 | AV38: BARPRO-SCREENMOUNT-VERTICALBAR | AW38: 1193 | BB38: 939-001799 | BC38: 5629 | BH38: S380-L4T1T | BI38: 1936 | BK38: SWM281 | BL38: 3442 | BW38: LS-6520X-24ST-SI-GL | BX38: 19021 | CL38: GB-ANALYTICS-ADV | CM38: 9086
A39: CP965 | B39: 7399 | C39: 12769 | D39: 15642 | O39: SHELLY EM GEN3 | P39: 1129.5856 | R39: L009UIGS-2HAXD-IN | S39: 1922 | U39: GS1915-8 | V39: 1428.665 | AA39: ER605 | AB39: 631 | AV39: BARPRO-TABLESTAND | AW39: 1420 | BB39: 939-001799-S | BC39: 5539 | BH39: HWA-01 | BI39: 2101 | BK39: DAP140 | BL39: 1018 | BW39: LS-1850V2-28P-EI-GL | BX39: 2345
A40: CPE90 | B40: 1176 | C40: 1680 | D40: 1740 | O40: SHELLY 120A CT PRO 3EM | P40: 346.38751 | R40: L009UIGS-RM | S40: 1610 | U40: GS1915-8EP | V40: 2645.676 | AA40: EX141 | AB40: 437 | AV40: BARPRO-WALLMOUNT | AW40: 1029 | BB40: 939-001802 | BC40: 12979 | BH40: ICD OPS I5 D | BI40: 15523 | BK40: RUTM30 | BL40: 7619 | BW40: LS-1850V2-52P-EI-GL | BX40: 4459
...

Sheet Categories
B2: Gauteng Tel: 010 824 0040 E-mail: sales@nology.co.za Cape Town Tel: 010 824 0044 E-mail: cptsales@nology.co.za
B9: CONSUMER | D9: NETWORKING | F9: UNIFIED COMMUNICATIONS
B26: E & OE Terms & Conditions: Pricing valid from 1 April 2026 until 30 April 2026. All pricing is Exclusive of VAT and subject to stock availability and lead times. Pricing is subject to change without notice and is linked to the exchange rate. CLICK HERE to view our full Terms and Conditions.

Sheet EOL Products
F1: Return
B6: END OF LIFE PRODUCTS
B12: SKU | C12: DESCRIPTION | D12: REPLACEMENT SKU | E12: REPLACEMENT DESCRIPTION | F12: COMMENTS
B13: D53G-5HacD2HnD-TC&RG502Q-EA | C13: Chateau 5G kit with 716MHz four core CPU, 256MB RAM, 5 x Gigabit LAN, two wireless interfaces (built-in 2.4Ghz 802.11b/g/n two chain wireless with integrated antennas, built-in 5Ghz 802.11ac two chain wireless with integrated antennas), RG502Q-EA LTE/5G modem for bands 1/3/5/7/8/18/19/20/26/28/32/34/38/39/40/41/42/43/77/78/79, two external and six internal LTE/5G antennas, tower case, USB, 1m RJ45 cable, PSU, RouterOS L4 | D13: S53UG+5HaxD2HaxD-TC&FG621-EA | E13: Chateau LTE6 ax with 1.8GHz four core CPU, 1GB RAM, 1 x 2.5 Gigabit LAN, 4 x Gigabit LAN, two wireless interfaces (built-in 2.4Ghz 802.11b/g/n/ax two chain wireless, built-in 5Ghz 802.11a/n/ac/ax two chain wireless) with external antennas, LTE CAT6 modem for International bands 1/3/5/7/8/20/28/38/40/41 with integrated antennas, SMA connectors for external antennas, tower case, USB, PSU, RouterOS L4, International version | F13: EOL
B14: MTAS-5G-15D120 | C14: MikroTik Dual-polarization 5Ghz 15dBi 120 degree beamwidth antenna with two RP-SMA connectors | D14: L22UGS-5HaxD2HaxD-15S (mANTBox ax 15s) | E14: mANTBox ax 15s with with dual-core ARM IPQ-5010 800MHz CPU, 256MB RAM, 1x2.5Gigabit SFP port, 1xGigabit LAN, built-in dual-band 2.4GHz 802.11b/g/n/ax dual-chain, 5GHz 802.11a/n/ac/ax dual-chain wireless, USB, RouterOS L4, outdoor enclosure, PSU, Gigabit PoE injector, pole mounting set (metal ring, quickMOUNT pro), integrated 2.4GHz 12 dBi and 5GHz 15 dBi sector antenna | F14: EOL
B15: RBLHGR | C15: MikroTik LHG 2G/3G/4G/LTE High Gain 17dBi CPE for Very Remote Areas (International Bands) | D15: LHGGR&FG621-EA | E15: LHGG LTE6 kit with 17dBi 25 degrees LTE directional antenna, 800MHz dual-core CPU, 256MB RAM, 1 x Gigabit Ethernet port (802.3af/at PoE-in), LTE CAT6 modem (R11eL-FG621-EA) for International bands 1/3/5/7/8/20/28/38/40/41, RouterOS L3, outdoor enclosure, PSU, PoE injector, pole mounting bracket | F15: EOL
B16: MTAD-5G-30D3-4STD | C16: MikroTik MTAD-5G-30D3-4STD Parabolic dish antenna for 5GHz, 30dBi gain (4-pack) | D16: MTAD-5G-30D3-4PA | E16: mANT 30dBi 5Ghz Parabolic Dish antenna with precision aligmnent mount, 4-pack (all four antennas in single box) | F16: EOL
B17: RBwAPR-2nD&R11e-LR8 | C17: MikroTik wAP LR8 Kit 2.4Ghz 2dBi LoraWAN Gateway | D17: RBwAPR-2nD&R11e-LR8G | E17: wAP LR8G kit for 863-870MHz frequency (European Union, India etc.) - 650MHz CPU, 64MB RAM, 1xLAN, built-in 2.4Ghz 802.11b/g/n Dual Chain wireless with integrated antenna, R11e-LR8G card, LoRa internal antenna with connector, RouterOS L4, outdoor enclosure, PSU, PoE injector | F17: EOL
B18: LtAP-2HnD&FG621-EA&LR8 | C18: MikroTik LtAP LR8 LTE kit with dual core 880MHz CPU, 128MB RAM, 1 x Gigabit LAN, built-in High Power 2.4Ghz 802.11b/g/n Dual Chain wireless with integrated antenna, LTE CAT6 modem for International bands 1/3/5/7/8/20/28/38/40/41 with with internal LTE antenna, GPS, LoRa miniPCI-e card for 863-870MHz frequency (European Union, India etc) with connector for external antenna, three miniSIM slots, RouterOS L4, outdoor enclosure, PSU | D18: LtAP-2HnD&FG621-EA&LR8G | E18: LtAP LR8G LTE kit with dual core 880MHz CPU, 128MB RAM, 1 x Gigabit LAN, built-in High Power 2.4Ghz 802.11b/g/n Dual Chain wireless with integrated antenna, LTE CAT6 modem for International bands 1/3/5/7/8/20/28/38/40/41 with with internal LTE antenna, GPS, LoRa R11e-LR8G miniPCI-e card for 863-870MHz frequency (European Union, India etc) with connector for external antenna, three miniSIM slots, RouterOS L4, outdoor enclosure, PSU | F18: EOL
B19: RB3011UiAS-RM | C19: MikroTik RouterBOARD RB3011UiAS, 10x GB LAN, 1x SFP port, RouterOS L5, 1U rACkmount case, LCD panel | D19: L009UiGS-RM, | E19: L009UiGS with dual core 800MHz CPU, 512MB RAM, 8 x Gbit LAN, 1 x 2.5 Gbit SFP port, USB, desktop/1U rackmount case, PSU, K-79 rackmount kit, RouterOS L5 | F19: EOL
B20: RB3011UiAS-RM | C20: MikroTik RouterBOARD RB3011UiAS, 10x GB LAN, 1x SFP port, RouterOS L5, 1U rACkmount case, LCD panel | D20: RB4011iGS+RM | E20: RouterBOARD 4011iGS+ with Annapurna Alpine AL21400 Cortex A15 CPU (4-cores, 1.4GHz per core), 1GB RAM, 10xGbit LAN, 1xSFP+ port, RouterOS L5, desktop case, rackmount ears, PSU | F20: EOL
B21: RB3011UiAS-RM | C21: MikroTik RouterBOARD RB3011UiAS, 10x GB LAN, 1x SFP port, RouterOS L5, 1U rACkmount case, LCD panel | D21: RB5009UG+S+IN | E21: RouterBORD 5009UG+S+ with Marvell Armada ARMv8 CPU (4-cores, 1.4GHz per core), 1GB of DDR4 RAM, 1GB NAND storage, 1x 2.5Gbit LAN, 7x 1Gbit LAN, 1x SFP+ port, RouterOS L5, metal desktop case, PSU | F21: EOL
B23: SIP PHONES
B24: SIP-T43U | C24: Yealink T43U Advanced Gb IP Phone With Dual USB Ports, Excludes PSU | D24: SIP-T73U | E24: Yealink T73U Gb IP Phone With USB Port, Excludes PSU | F24: EOL / Last Stock Replacement Available
B25: SIP-T44W | C25: Yealink T44W Gigabit Desktop IP Phone With Built-in Wi-Fi, Bluetooth And Dual USB Ports, Excludes PSU | D25: SIP-T73W | E25: Yealink T73W Multifunctional SIP Phone, Wi-Fi, Built-in Bluetooth, PoE support, Excludes PSU | F25: EOL / Last Stock Replacement Available
B26: SIP-T48U | C26: Yealink T48U Gb IP Phone With 7" Touch LCD And Dual USB Ports, Excludes PSU | D26: SIP-T77U | E26: Yealink T77U SIP Phone With 7" Touch Screen, Dual-port Gigabit Ethernet, PoE Support, Dual USB Ports | F26: EOL / Last Stock Replacement Available
B27: SIP-T57W | C27: Yealink T57W Dual Band IP Desktop Phone, Excludes PSU | D27: SIP-T87W | E27: Yealink T87W Prime Business Phone, 7" Touch Screen, Built-In Bluetooth, Wi-Fi, PoE Support, Excludes PSU | F27: EOL / Last Stock Replacement Available
B28: IP CONFERENCE PHONES
B29: CPW65 | C29: Yealink CPW65 Wireless DECT Microphones For CP965 | F29: EOL / LAST STOCK
B30: USB HEADSETS
B31: UH34-SE-MONO-USBC | C31: Yealink UH34 Mono Headset Special Edition With USB-C Connection, Teams Edition | D31: UH42 MONO TEAMS USB-C/A | E31: Yealink UH42 Mono USB Headset, USB-C With USB-C/A Adapter, Teams Certified | F31: EOL / Last Stock Replacement Available
B32: UH34-SE-DUAL-USBC | C32: Yealink UH34 Dual Headset Special Edition With USB-C Connection, Teams Edition | D32: UH42 DUAL TEAMS USB-C/A | E32: Yealink UH42 Dual USB Headset, USB-C With USB-C/A Adapter, Teams Certified | F32: EOL / Last Stock Replacement Available
B33: UH36-MONO-USBC | C33: Yealink UH36 Mono Headset With USB-C Connection (EOL) | D33: UH37 MONO TEAMS USB-C/A | E33: Yealink UH37 Mono USB Headset, USB-C With USB-C/A Adapter, Teams Certified | F33: EOL / Last Stock Replacement Available
B34: UH37 MONO TEAMS USB-C/A | C34: Yealink UH37 Mono USB Headset, USB-C With USB-C/A Adapter, Teams Certified | D34: UH46 MONO TEAMS USB-C/A | E34: Yealink UH46 Mono USB Headset, USB-C With USB-C/A Adapter, Teams Certified | F34: EOL / Last Stock Replacement Available
B35: UH37 DUAL TEAMS USB-C/A | C35: Yealink UH37 Dual USB Headset, USB-C With USB-C/A Adapter, Teams Certified | D35: UH46 DUAL TEAMS USB-C/A | E35: Yealink UH46 Dual USB Headset, USB-C With USB-C/A Adapter, Teams Certified | F35: EOL / Last Stock Replacement Available
B36: DECT WIRELESS HEADSETS
B37: WH62-DUAL | C37: Yealink WH62-Dual DECT Wireless On Ear Dual Headset (EOL) | F37: EOL / LAST STOCK
B38: WH64-HYBRID-MONO | C38: Yealink WH64 Hybrid Mono DECT And Bluetooth Hybrid Wireless Headset, Teams Certified, Includes Dongle, Does Not Include Stand | F38: EOL / LAST STOCK
B39: WH68 HYBRID TEAMS | C39: Yealink WH68 Hybrid DECT Wireless Headset, Teams Certified | F39: EOL / LAST STOCK
B40: RJ-9 HEADSETS
B41: YHS34-LITE-MONO | C41: Yealink YHS34 Lite Mono Headset With RJ-9 And Foam Ear Cushions | D41: YHS34-MONO | E41: =VLOOKUP(D41,[1]Yealink!B:G,2,0) -> Yealink YHS34 Mono Headset With RJ-9 And Leatherette Ear Cushions | F41: EOL / Last Stock Replacement Available
B42: YHS34-LITE-DUAL | C42: Yealink YHS34 Lite Dual Headset With RJ-9 And Foam Ear Cushions | D42: YHS34-DUAL | E42: =VLOOKUP(D42,[1]Yealink!B:G,2,0) -> Yealink YHS34 Dual Headset With RJ-9 And Leatherette Ear Cushions | F42: EOL / Last Stock Replacement Available
B43: YHS36-MONO | C43: Yealink YHS36 Mono Headset With RJ-9 And Leatherette Ear Cushions | D43: YHS36 E2 MONO | E43: Yealink YHS36 E2 Mono Headset With RJ-9 And noise Cancelling Microphone And Leatherette Ear Cushions | F43: EOL / Last Stock Replacement Coming Soon
B44: YHS36-DUAL | C44: Yealink YHS36 Dual Headset With RJ-9 And Leatherette Ear Cushions | D44: YHS36 E2 DUAL | E44: Yealink YHS36 E2 Dual Headset With RJ-9 And Noise Cancelling Microphone And Leatherette Ear Cushions | F44: EOL / Last Stock Replacement Coming Soon
B47: SHELLY BLU BUTTON1 (BLACK) | C47: Shelly BLU Button1 (Black) Bluetooth Button For Operated Actions And Scene Activation | F47: EOL, last stock PROMOTION
B48: SHELLY BLU BUTTON1 (BLUE) | C48: Shelly BLU Button1 (Blue) Bluetooth Button For Operated Actions And Scene Activation | F48: EOL, last stock PROMOTION
B49: SHELLY BLU BUTTON1 (RED) | C49: Shelly BLU Button1 (Red) Bluetooth Button For Operated Actions And Scene Activation | F49: EOL, last stock PROMOTION
B50: SHELLY DUO CW/WW (E27) | C50: Shelly Duo CW/WW (E27) Smart Cool Or Warm White Dimmable Bulb | F50: EOL, last stock PROMOTION
B51: SHELLY VINTAGE A60 (E27) | C51: Shelly Vintage A60 (E27) Dimmable Smart Bulb | F51: EOL, last stock PROMOTION
B52: SHELLY VINTAGE G125 (E27) | C52: Shelly Vintage G125 (E27) Dimmable Smart Bulb | F52: EOL, last stock PROMOTION
...

Sheet Promotions
H1: Return
B6: PROMOTIONS
C9: YEALINK VOICE PROMOTION
C10: SKU | D10: DESCRIPTION | E10: PRICE | F10: Suggested advertising price | G10: MSRP | H10: COMMENTS
C11: IP DESKTOP PHONES
C12: SIP-T48U | D12: Yealink T48U Gb IP Phone With 7" Touch LCD And Dual USB Ports, Excludes PSU | E12: =_xlfn.XLOOKUP(C12,PRICING!A:A,PRICING!B:B,"No Record",0,1) -> 2849 | F12: =INDEX(PRICING!C:C,MATCH(C12,PRICING!A:A,0),1) -> 4603 | G12: =INDEX(PRICING!D:D,MATCH(C12,PRICING!A:A,0),1) -> 5550 | H12: PROMOTION + Extra 5% discount when ordering 5 or more units
C13: SIP-T44W | D13: Yealink T44W Gigabit Desktop IP Phone With Built-in Wi-Fi, Bluetooth And Dual USB Ports, Excludes PSU | E13: =_xlfn.XLOOKUP(C13,PRICING!A:A,PRICING!B:B,"No Record",0,1) -> 1648 | F13: =INDEX(PRICING!C:C,MATCH(C13,PRICING!A:A,0),1) -> 2688 | G13: =INDEX(PRICING!D:D,MATCH(C13,PRICING!A:A,0),1) -> 3288 | H13: PROMOTION + Extra 5% discount when ordering 5 or more units
C14: SIP-T43U | D14: Yealink T43U Advanced Gb IP Phone With Dual USB Ports, Excludes PSU | E14: =_xlfn.XLOOKUP(C14,PRICING!A:A,PRICING!B:B,"No Record",0,1) -> 1398 | F14: =INDEX(PRICING!C:C,MATCH(C14,PRICING!A:A,0),1) -> 2251 | G14: =INDEX(PRICING!D:D,MATCH(C14,PRICING!A:A,0),1) -> 2940 | H14: PROMOTION + Extra 5% discount when ordering 5 or more units
C15: SIP-T57W | D15: Yealink T57W Dual Band IP Desktop Phone, Excludes PSU | E15: =_xlfn.XLOOKUP(C15,PRICING!A:A,PRICING!B:B,"No Record",0,1) -> 3299 | F15: =INDEX(PRICING!C:C,MATCH(C15,PRICING!A:A,0),1) -> 5645 | G15: =INDEX(PRICING!D:D,MATCH(C15,PRICING!A:A,0),1) -> 6246 | H15: PROMOTION + Extra 5% discount when ordering 5 or more units
C16: IP VIDEO PHONE
C17: VP59 | D17: Yealink VP59 Video Phone For Video Conference Calls, Excludes PSU | E17: =_xlfn.XLOOKUP(C17,PRICING!A:A,PRICING!B:B,"No Record",0,1) -> 7598 | F17: =INDEX(PRICING!C:C,MATCH(C17,PRICING!A:A,0),1) -> 12198 | G17: =INDEX(PRICING!D:D,MATCH(C17,PRICING!A:A,0),1) -> 13902 | H17: PROMOTION
C18: IP CONFERENCE PHONE
C19: CP965 | D19: Yealink CP965 Android IP Conference Phone (SIP ONLY) | E19: =_xlfn.XLOOKUP(C19,PRICING!A:A,PRICING!B:B,"No Record",0,1) -> 7399 | F19: =INDEX(PRICING!C:C,MATCH(C19,PRICING!A:A,0),1) -> 12769 | G19: =INDEX(PRICING!D:D,MATCH(C19,PRICING!A:A,0),1) -> 15642 | H19: PROMOTION
C20: IP DECT PHONE
C21: W59R | D21: Yealink W59R Rugged DECT Handset IP67 | E21: =_xlfn.XLOOKUP(C21,PRICING!A:A,PRICING!B:B,"No Record",0,1) -> 1798 | F21: =INDEX(PRICING!C:C,MATCH(C21,PRICING!A:A,0),1) -> 2940 | G21: =INDEX(PRICING!D:D,MATCH(C21,PRICING!A:A,0),1) -> 2940 | H21: PROMOTION
C22: W90B | D22: Yealink W90B Multi-Cell DECT Base Station | E22: =_xlfn.XLOOKUP(C22,PRICING!A:A,PRICING!B:B,"No Record",0,1) -> 3498 | F22: =INDEX(PRICING!C:C,MATCH(C22,PRICING!A:A,0),1) -> 5544 | G22: =INDEX(PRICING!D:D,MATCH(C22,PRICING!A:A,0),1) -> 8160 | H22: PROMOTION
C23: MP PHONE
C24: MP52 E2 | D24: Yealink MP52 E2 Basic Phone For Microsoft Teams Excludes PSU | E24: =_xlfn.XLOOKUP(C24,PRICING!A:A,PRICING!B:B,"No Record",0,1) -> 2199 | F24: =INDEX(PRICING!C:C,MATCH(C24,PRICING!A:A,0),1) -> 4110 | G24: =INDEX(PRICING!D:D,MATCH(C24,PRICING!A:A,0),1) -> 3984 | H24: PROMOTION
C25: USB HEADSETS
C26: UH34-MONO | D26: Yealink UH34 Mono Single Earpiece USB Headset With Leatherette Ear Cushions Teams Edition | E26: =_xlfn.XLOOKUP(C26,PRICING!A:A,PRICING!B:B,"No Record",0,1) -> 369 | F26: =INDEX(PRICING!C:C,MATCH(C26,PRICING!A:A,0),1) -> 614 | G26: =INDEX(PRICING!D:D,MATCH(C26,PRICING!A:A,0),1) -> 895 | H26: PROMOTION
C27: UH34-DUAL | D27: Yealink UH34 Dual Earpiece USB Headset With Leatherette Ear Cushions Teams Edition | E27: =_xlfn.XLOOKUP(C27,PRICING!A:A,PRICING!B:B,"No Record",0,1) -> 499 | F27: =INDEX(PRICING!C:C,MATCH(C27,PRICING!A:A,0),1) -> 835 | G27: =INDEX(PRICING!D:D,MATCH(C27,PRICING!A:A,0),1) -> 1200 | H27: PROMOTION
C28: UH34-SE-DUAL-USBC | D28: Yealink UH34 Dual Headset Special Edition With USB-C Connection, Teams Edition | E28: =_xlfn.XLOOKUP(C28,PRICING!A:A,PRICING!B:B,"No Record",0,1) -> 599 | F28: =INDEX(PRICING!C:C,MATCH(C28,PRICING!A:A,0),1) -> 989 | G28: =INDEX(PRICING!D:D,MATCH(C28,PRICING!A:A,0),1) -> 1653 | H28: PROMOTION
C29: UH34 SE DUAL USB A | D29: Yealink UH34 Dual Headset Special Edition With USB-A, 3.5mm jack Connection, Teams edition | E29: =_xlfn.XLOOKUP(C29,PRICING!A:A,PRICING!B:B,"No Record",0,1) -> 579 | F29: =INDEX(PRICING!C:C,MATCH(C29,PRICING!A:A,0),1) -> 955 | G29: =INDEX(PRICING!D:D,MATCH(C29,PRICING!A:A,0),1) -> 1600 | H29: PROMOTION
C30: UH36-MONO-USBC | D30: Yealink UH36 Mono Headset With USB-C Connection | E30: =_xlfn.XLOOKUP(C30,PRICING!A:A,PRICING!B:B,"No Record",0,1) -> 669 | F30: =INDEX(PRICING!C:C,MATCH(C30,PRICING!A:A,0),1) -> N/A | G30: =INDEX(PRICING!D:D,MATCH(C30,PRICING!A:A,0),1) -> N/A | H30: PROMOTION
C31: DECT WIRELESS HEADSETS
C32: WH66-MONO | D32: Yealink WH66 Mono DECT Wireless On Ear Mono Headset With Touch Screen Base Station | E32: =_xlfn.XLOOKUP(C32,PRICING!A:A,PRICING!B:B,"No Record",0,1) -> 3198 | F32: =INDEX(PRICING!C:C,MATCH(C32,PRICING!A:A,0),1) -> 5049 | G32: =INDEX(PRICING!D:D,MATCH(C32,PRICING!A:A,0),1) -> 6010 | H32: PROMOTION
C33: WH66-DUAL | D33: Yealink WH66 Dual DECT Wireless On Ear Stereo Headset With Touch Screen Base Station | E33: =_xlfn.XLOOKUP(C33,PRICING!A:A,PRICING!B:B,"No Record",0,1) -> 3398 | F33: =INDEX(PRICING!C:C,MATCH(C33,PRICING!A:A,0),1) -> 5458 | G33: =INDEX(PRICING!D:D,MATCH(C33,PRICING!A:A,0),1) -> 6558 | H33: PROMOTION
C34: WH67 | D34: Yealink WH67 DECT Wireless Convertible Headset With Touch Screen Base Station | E34: =_xlfn.XLOOKUP(C34,PRICING!A:A,PRICING!B:B,"No Record",0,1) -> 2999 | F34: =INDEX(PRICING!C:C,MATCH(C34,PRICING!A:A,0),1) -> 4844 | G34: =INDEX(PRICING!D:D,MATCH(C34,PRICING!A:A,0),1) -> 5828 | H34: PROMOTION
C35: WH68 HYBRID TEAMS | D35: Yealink WH68 Hybrid DECT Wireless Headset, Teams Certified | E35: =_xlfn.XLOOKUP(C35,PRICING!A:A,PRICING!B:B,"No Record",0,1) -> 1999 | F35: =INDEX(PRICING!C:C,MATCH(C35,PRICING!A:A,0),1) -> 3275 | G35: =INDEX(PRICING!D:D,MATCH(C35,PRICING!A:A,0),1) -> 4158 | H35: PROMOTION
C36: WH68 DUAL | D36: Yealink WH68 Dual DECT Wireless Headset | E36: =_xlfn.XLOOKUP(C36,PRICING!A:A,PRICING!B:B,"No Record",0,1) -> 2498 | F36: =INDEX(PRICING!C:C,MATCH(C36,PRICING!A:A,0),1) -> 4094 | G36: =INDEX(PRICING!D:D,MATCH(C36,PRICING!A:A,0),1) -> 5202 | H36: PROMOTION
C37: RJ & QD HEADSETS
C38: YHS36-MONO | D38: Yealink YHS36 Mono Headset With RJ-9 And Leatherette Ear Cushions | E38: =_xlfn.XLOOKUP(C38,PRICING!A:A,PRICING!B:B,"No Record",0,1) -> 459 | F38: =INDEX(PRICING!C:C,MATCH(C38,PRICING!A:A,0),1) -> 750 | G38: =INDEX(PRICING!D:D,MATCH(C38,PRICING!A:A,0),1) -> 895 | H38: PROMOTION
C39: ACCESSORIES
C40: CAM50 | D40: Yealink CAM50 USB Camera For Use With T58W (PRO) | E40: =_xlfn.XLOOKUP(C40,PRICING!A:A,PRICING!B:B,"No Record",0,1) -> 1149 | F40: =INDEX(PRICING!C:C,MATCH(C40,PRICING!A:A,0),1) -> 1775.1 | G40: =INDEX(PRICING!D:D,MATCH(C40,PRICING!A:A,0),1) -> 2013 | H40: PROMOTION
C42: YEALINK VC PROMOTION
C43: SKU | D43: DESCRIPTION | E43: PRICE | F43: Suggested advertising price | G43: MSRP | H43: COMMENTS
C44: ROOM CAMERAS & AUDIO DEVICE & BYOD KIT
C45: MTOWER | D45: Yealink MTower Center-view Intelligent Camera | E45: =_xlfn.XLOOKUP(C45,PRICING!A:A,PRICING!B:B) -> 18798 | F45: =_xlfn.XLOOKUP(C45,PRICING!A:A,PRICING!C:C) -> 29562 | G45: =_xlfn.XLOOKUP(C45,PRICING!A:A,PRICING!D:D) -> 29562 | H45: PROMOTION 2 YEAR WARRANTY
C46: BYOD-BOX | D46: Yealink BYOD Connection Box | E46: =_xlfn.XLOOKUP(C46,PRICING!A:A,PRICING!B:B) -> 1199 | F46: =_xlfn.XLOOKUP(C46,PRICING!A:A,PRICING!C:C) -> 2088 | G46: =_xlfn.XLOOKUP(C46,PRICING!A:A,PRICING!D:D) -> 2940 | H46: PROMOTION 2 YEAR WARRANTY
C47: ROOM AUDIO DEVICE
...

Sheet New Products
G1: Return
B7: NEW PRODUCTS
B11: SKU | C11: DESCRIPTION | D11: PRICE | E11: Suggested advertising price | F11: MSRP | G11: COMMENTS
B12: IP DECT PHONES
B13: W59R PRO | C13: Yealink W59R PRO Rugged DECT Handset IP67 | D13: =_xlfn.XLOOKUP(B13,PRICING!A:A,PRICING!B:B,"No Record",0,1) -> 2069 | E13: =INDEX(PRICING!C:C,MATCH(B13,PRICING!A:A,0),1) -> 2940 | F13: =INDEX(PRICING!D:D,MATCH(B13,PRICING!A:A,0),1) -> 2940 | G13: COMING SOON 2 YEAR WARRANTY
B14: DECT WIRELESS HEADSETS
B15: WH63 E2 | C15: Yealink WH63 E2 DECT Wireless Convertible Headset, MS Teams Certified | D15: =_xlfn.XLOOKUP(B15,PRICING!A:A,PRICING!B:B,"No Record",0,1) -> 1886 | E15: =INDEX(PRICING!C:C,MATCH(B15,PRICING!A:A,0),1) -> 2695 | F15: =INDEX(PRICING!D:D,MATCH(B15,PRICING!A:A,0),1) -> 3305 | G15: NEW 2 YEAR WARRANTY
B16: WH68 HYBRID WITH CHARGE STAND | C16: Yealink WH68 Hybrid DECT Wireless Headset, Teams Certified, with Charging Stand | D16: =_xlfn.XLOOKUP(B16,PRICING!A:A,PRICING!B:B,"No Record",0,1) -> 2436 | E16: =INDEX(PRICING!C:C,MATCH(B16,PRICING!A:A,0),1) -> 3480 | F16: =INDEX(PRICING!D:D,MATCH(B16,PRICING!A:A,0),1) -> 4332 | G16: COMING SOON 2 YEAR WARRANTY
B17: TEAMS PHONES
B18: MP55 E2 | C18: Yealink MP55 E2 Phone For Microsoft Teams, Excludes PSU | D18: =_xlfn.XLOOKUP(B18,PRICING!A:A,PRICING!B:B,"No Record",0,1) -> 3788 | E18: =INDEX(PRICING!C:C,MATCH(B18,PRICING!A:A,0),1) -> 5412 | F18: =INDEX(PRICING!D:D,MATCH(B18,PRICING!A:A,0),1) -> 5550 | G18: COMING SOON 2 YEAR WARRANTY
B19: USB HEADSETS
B20: UH42 SE DUAL TEAMS USB-C/A | C20: Yealink UH42 SE Dual USB Headset, USB-C With USB-C/A Adapter, Teams Certified | D20: =_xlfn.XLOOKUP(B20,PRICING!A:A,PRICING!B:B,"No Record",0,1) -> 597 | E20: =INDEX(PRICING!C:C,MATCH(B20,PRICING!A:A,0),1) -> 852 | F20: =INDEX(PRICING!D:D,MATCH(B20,PRICING!A:A,0),1) -> N/A | G20: COMING SOON 2 YEAR WARRANTY
B21: UH42 SE MONO TEAMS USB-C/A | C21: Yealink UH42 SE Mono USB Headset, USB-C With USB-C/A Adapter, Teams Certified | D21: =_xlfn.XLOOKUP(B21,PRICING!A:A,PRICING!B:B,"No Record",0,1) -> 477 | E21: =INDEX(PRICING!C:C,MATCH(B21,PRICING!A:A,0),1) -> 682 | F21: =INDEX(PRICING!D:D,MATCH(B21,PRICING!A:A,0),1) -> N/A | G21: COMING SOON 2 YEAR WARRANTY
B22: VIDEO CONFERENCING DEVICES
B23: SKU | C23: DESCRIPTION | D23: PRICE | E23: Suggested advertising price | F23: MSRP | G23: COMMENTS
B24: A-SERIES ALL-IN-ONE VIDEO BARS FOR MICROSOFT TEAMS
B25: A25-010 | C25: Yealink A25 all-in-one Collaboration bar for focus rooms, Incl VCR11 Remote | D25: =INDEX(PRICING!B:B,MATCH(B25,PRICING!A:A,0),1) -> 20079 | E25: =INDEX(PRICING!C:C,MATCH(B25,PRICING!A:A,0),1) -> 27822 | F25: =INDEX(PRICING!D:D,MATCH(B25,PRICING!A:A,0),1) -> 27822 | G25: NEW 2 YEAR WARRANTY
B26: A25-031 | C26: Yealink A25 all-in-one Collaboration bar for focus rooms, incl. CTP25 touch console | D26: =INDEX(PRICING!B:B,MATCH(B26,PRICING!A:A,0),1) -> 27613 | E26: =INDEX(PRICING!C:C,MATCH(B26,PRICING!A:A,0),1) -> 40002 | F26: =INDEX(PRICING!D:D,MATCH(B26,PRICING!A:A,0),1) -> 40002 | G26: NEW 2 YEAR WARRANTY
B27: MEETINGBOARD
B28: MB65C-EDLA | C28: Yealink MeetingBoard 65C for Small and Medium Rooms, Manager Office - 65-inch all-in-one Collaboration Display, Google EDLA certified, Google Play, Supports casting, Whiteboard, USB-BYOD | D28: =INDEX(PRICING!B:B,MATCH(B28,PRICING!A:A,0),1) -> 38976 | E28: =INDEX(PRICING!C:C,MATCH(B28,PRICING!A:A,0),1) -> 52182 | F28: =INDEX(PRICING!D:D,MATCH(B28,PRICING!A:A,0),1) -> 52182 | G28: NEW 2 YEAR WARRANTY
B29: MB75C-EDLA | C29: Yealink MeetingBoard 75C for Small and Medium Rooms, Manager Office - 75-inch all-in-one Collaboration Display, Google EDLA certified, Google Play, Supports casting, Whiteboard, USB-BYOD | D29: =INDEX(PRICING!B:B,MATCH(B29,PRICING!A:A,0),1) -> 44000 | E29: =INDEX(PRICING!C:C,MATCH(B29,PRICING!A:A,0),1) -> 69582 | F29: =INDEX(PRICING!D:D,MATCH(B29,PRICING!A:A,0),1) -> 69582 | G29: NEW 2 YEAR WARRANTY
B30: ROOM AUDIO
B31: MSPEAKER PRO | C31: Yealink MSpeaker Pro Soundbar For Video Conferencing | D31: =INDEX(PRICING!B:B,MATCH(B31,PRICING!A:A,0),1) -> 4872 | E31: =INDEX(PRICING!C:C,MATCH(B31,PRICING!A:A,0),1) -> 6942 | F31: =INDEX(PRICING!D:D,MATCH(B31,PRICING!A:A,0),1) -> 6942 | G31: NEW 2 YEAR WARRANTY
B32: CPE40 | C32: Yealink CPE40 Speakerphone, works with CP50 | D32: =INDEX(PRICING!B:B,MATCH(B32,PRICING!A:A,0),1) -> 3654 | E32: =INDEX(PRICING!C:C,MATCH(B32,PRICING!A:A,0),1) -> 5481 | F32: =INDEX(PRICING!D:D,MATCH(B32,PRICING!A:A,0),1) -> 6072 | G32: NEW 2 YEAR WARRANTY
B33: CP50 | C33: Yealink CP50 Speaker for UVC85 Video Conferencing | D33: =INDEX(PRICING!B:B,MATCH(B33,PRICING!A:A,0),1) -> 5359 | E33: =INDEX(PRICING!C:C,MATCH(B33,PRICING!A:A,0),1) -> 8038 | F33: =INDEX(PRICING!D:D,MATCH(B33,PRICING!A:A,0),1) -> 8682 | G33: NEW 2 YEAR WARRANTY
B34: ACCESSORIES
B35: MB-12X PRO | C35: Yealink 12x PTZ Camera Module for MeetingBoard Pro Only | D35: =INDEX(PRICING!B:B,MATCH(B35,PRICING!A:A,0),1) -> 14128 | E35: =INDEX(PRICING!C:C,MATCH(B35,PRICING!A:A,0),1) -> 17382 | F35: =INDEX(PRICING!D:D,MATCH(B35,PRICING!A:A,0),1) -> 17382 | G35: NEW 2 YEAR WARRANTY
B36: ROOMSENSOR PRO | C36: Yealink RoomSensor Pro Multifunctional Wireless Sensor | D36: =INDEX(PRICING!B:B,MATCH(B36,PRICING!A:A,0),1) -> 4263 | E36: =INDEX(PRICING!C:C,MATCH(B36,PRICING!A:A,0),1) -> 6403 | F36: =INDEX(PRICING!D:D,MATCH(B36,PRICING!A:A,0),1) -> 6594 | G36: NEW 2 YEAR WARRANTY
B39: SKU | C39: DESCRIPTION | D39: PRICE | G39: COMMENTS
B40: ENTERPRISE POE ACCESS SWITCHES
B41: LS-5130S-28P-HPWR-EI-AC-GL | C41: H3C S5130S-28P-HPWR-EI-AC L2 Ethernet Switch with 24x 10/100/1000BASE-T PoE+ Ports (AC 370W), 4x 100/1000BASE-X SFP Ports, and 4x GE Combo Ports, (AC) | D41: P.O.R | G41: NOW IN STOCK
B42: LS-5130S-52P-PWR-EI-AC-GL | C42: H3C S5130S-52P-PWR-EI-AC L2 Ethernet Switch with 48x 10/100/1000BASE-T PoE+ Ports (AC 370W) and 4x 1000BASE-X SFP Ports, (AC) | D42: P.O.R | G42: NOW IN STOCK
B43: LS-5170-28S-HPWR-EI-GL | C43: H3C S5170-28S-HPWR-EI L2 Ethernet Switch with 24x 10/100/1000BASE-T Ports and 4x 1G/10G BASE-X SFP Plus Ports, (AC), PoE+ | D43: P.O.R | G43: NOW IN STOCK
B44: ENTERPRISE WIRELESS ACCESS POINTS
B45: EWP-WA6520-FIT | C45: H3C WA6520 Internal Antennas 4 Streams Dual Radio 802.11ax/ac/n Access Point,FIT | D45: P.O.R | G45: NOW IN STOCK
B46: EWP-WA6528I-FIT | C46: H3C WA6528i Internal Antennas 8 Streams Dual Radio 802.11ax/ac/n Access Point, FIT | D46: P.O.R | G46: NOW IN STOCK
B47: EWP-WA6620X-FIT | C47: H3C WA6620X Integrated Internal and External Antennas 4 Streams Dual Radio 802.11ax/ac/n External Access Point | D47: P.O.R | G47: NOW IN STOCK
B50: SKU | C50: DESCRIPTION | D50: PRICE | G50: COMMENTS
B51: RUTC41 | C51: Teltonika Teltonika RUTC41 4G LTE (Cat 4) Router, WIFI 6, 1 x WAN, 4 x LAN, eSIM | D51: 5426 | G51: Coming Soon
B52: RUT976 | C52: Teltonika RUT976 Redcap 5G LTE Cat 4 GNSS antenna OR DinRail Router, eSIM + Dual-SIM, 1 x WAN (100 Mbps), 3 x WAN (100 Mbps), MODUBUS RS232/RS485 | D52: 6150 | G52: Coming Soon
...

Sheet Warehouse Clearance 
K1: Return
B6: WAREHOUSE CLEARANCE
D7: ** Please refer to the condition column for information about the products listed here.**
A10: Unified Communication
B11: Brand | C11: Code | D11: Product Description | E11: QTY Available | F11: Standard Price | G11: Warehouse Clearance Price | H11: Condition | I11: Warehouse | J11: Warranty | K11: Comments
B12: Jabra | C12: EVOLVE-40-MONO | D12: Jabra Evolve 40 Mono USB Headset | E12: 1 | F12: 1005 | G12: 905 | H12: Excellent / Sealed | I12: Gauteng | J12: Warranty expired | K12: Add Nology BB Warranty-12
B13: Yealink | C13: MB65-A001 | D13: Yealink MeetingBoard65 For Small And Medium Rooms: Includes 1X 65 Inch All-In-One Collaboration Display, Power Adapter, Wall Mount Bracket And Cables, 4 X Stylus Pen | E13: 1 | F13: =_xlfn.XLOOKUP(C13,PRICING!A181:A493,PRICING!D181:D493) -> 83502 | G13: 39755.55 | H13: Available on request | I13: Gauteng | J13: Warranty expired | K13: Clearance Price Add Nology BB Warranty-12
B14: Yealink | C14: MCOREKIT-C5-MS | D14: Yealink MCore Base Kit including mini-PC, MTouch Plus and RoomSensor | E14: 1 | F14: =_xlfn.XLOOKUP(C14,PRICING!A182:A494,PRICING!D182:D494) -> 43482 | G14: 29646.16 | H14: Available on request | I14: Gauteng | J14: Warranty expired | K14: Clearance Price Add Nology BB Warranty-12
B15: Yealink | C15: MD65 | D15: Yealink MeetingDisplay 65 inch | E15: 1 | F15: =_xlfn.XLOOKUP(C15,PRICING!A183:A495,PRICING!D183:D495) -> 29562 | G15: 13972.45 | H15: Available on request | I15: Gauteng | J15: Warranty expired | K15: Clearance Price Add Nology BB Warranty-12
B16: Yealink | C16: MVC S60-C5-000 | D16: Yealink MVC S60-C5-000 Teams Room System for Small to Medium Rooms incl. S60 Intelligent All-in-One Device, MCore Pro, MTouch Plus, RoomSensor | E16: 1 | F16: =_xlfn.XLOOKUP(C16,PRICING!A184:A496,PRICING!D184:D496) -> 93942 | G16: 66120.36 | H16: Available on request | I16: Gauteng | J16: Under warranty till 05-03-2026
B17: Yealink | C17: MVC300 | D17: Yealink MVC300, UVC30 Camera, MTouch | E17: 1 | F17: =_xlfn.XLOOKUP(C17,PRICING!A185:A497,PRICING!D185:D497) -> #N/A | G17: 27877 | H17: Available on request | I17: Gauteng | J17: Warranty expired | K17: Add Nology BB Warranty-12
B18: Yealink | C18: MVC640-C3-050 | D18: Yealink MVC640 Full HD Video Conferencing Solution Incl: UVC84 Camera, MTouch II, MSpeech AI Speakerphone And Mini-PC | E18: 2 | F18: 56706 | G18: 39338.01 | H18: Available on request | I18: Gauteng | J18: Warranty expired | K18: Add Nology BB Warranty-12
B19: Yealink | C19: MVC640-C4-F13 | D19: Yealink MVC640 Microsoft Teams Rooms System For Medium-To-Large Rooms, Incl. UVC84, MCore Pro Kit C4(MCore Pro Mini-PC, MTouch E2), VCR20, Mspeaker II, 2x CPW65, WPP30 | E19: 1 | F19: =_xlfn.XLOOKUP(C19,PRICING!A187:A499,PRICING!D187:D499) -> #N/A | G19: 39338.01 | H19: Available on request | I19: Gauteng | J19: No Warranty | K19: Add Nology BB Warranty-6
B20: Yealink | C20: UVC85 | D20: Yealink UVC85 4K 12X PTZ USB Camera | E20: 1 | F20: =_xlfn.XLOOKUP(C20,PRICING!A188:A500,PRICING!D188:D500) -> 14772 | G20: 9843.91 | H20: Available on request | I20: Gauteng | J20: Warranty expired | K20: Add Nology BB Warranty-12
B21: Yealink | C21: MP56 | D21: Yealink MP56 Android Phone, For MS Teams, Excludes PSU (EOL) | E21: 1 | F21: 3666 | G21: 1199 | H21: Available on request | I21: Cape Town | J21: Supplier warranty till 22-12-2025
B22: Yealink | C22: BH76-BLK-ST-USBA | D22: Yealink BH76 Headset, Black with Charging Stand, USB-A Connection, Teams Certified (EOL) | E22: 1 | F22: 2368 | G22: 1659 | H22: Available on request | I22: Gauteng | J22: Warranty expired | K22: Add Nology BB Warranty-12
B23: Yealink | C23: BT41 | D23: Yealink BT41 Bluetooth USB Dongle | E23: 2 | F23: 358 | G23: 249 | H23: Available on request | I23: Gauteng | J23: Warranty expired
B24: Yealink | C24: BT51-A-S | D24: Yealink BT51-A Bluetooth USB-A Dongle Compatible With BH72 Lite/BH72/BH76 | E24: 1 | F24: 358 | G24: 249 | H24: Available on request | I24: Gauteng | J24: Warranty expired
B25: Yealink | C25: CP965 | D25: Yealink CP965 Android IP Conference Phone (SIP ONLY) | E25: 1 | F25: 7399 | G25: 5179 | H25: Available on request | I25: Gauteng | J25: Supplier warranty till 02-01-2025 | K25: Add Nology BB Warranty-12
B26: Yealink | C26: CPE90 | D26: Yealink CPE90 Wired Expansion Microphones For CP960 | E26: 3 | F26: 1176 | G26: 829 | H26: Available on request | I26: Gauteng | J26: Warranty expired
B27: Yealink | C27: EHS60 | D27: Yealink EHS60 Wireless Headset Adapter For WH62, WH63, X1 Micro USB Port, X1 RJ45 (8P8C), X1 RJ9 (4P4C) Headset Jacks | E27: 8 | F27: 477 | G27: 339 | H27: Available on request | I27: Gauteng | J27: Supplier warranty till 03-08-2026
B28: Yealink | C28: EXP43 | D28: Yealink EXP43 LCD Expansion Module For T43U, T46U And T48U Phones | E28: 1 | F28: 1246 | G28: 879 | H28: Available on request | I28: Gauteng | J28: Warranty expired
B29: Yealink | C29: MP52 | D29: Yealink MP52 Basic Phone For MS Teams Excludes PSU (EOL) | E29: 10 | F29: 2550 | G29: 1109 | H29: Available on request | I29: Gauteng | J29: Under warranty till 22-12-2025
B30: Yealink | C30: PSU-COLOUR | D30: Yealink PSU Colour For 5V/2A PSU For T44W, T46U, T48U, T54W, T57W, T74W, T73U, T74U, T58W, T87W and MP5x Series | E30: 2 | F30: 129 | G30: 89 | H30: Available on request | I30: Gauteng | J30: Under warranty till 18-12-2025
B31: Yealink | C31: SIP-T30 | D31: Yealink T30 Single Line Entry Level IP Phone, No PoE, Includes PSU | E31: 2 | F31: 642 | G31: 449 | H31: Available on request | I31: Gauteng | J31: Under warranty till 04-01-2026
B32: Yealink | C32: SIP-T31P | D32: Yealink SIP-T31P 10/100 Desktop IP Phone, Excludes PSU | E32: 2 | F32: 752 | G32: 529 | H32: Available on request | I32: Gauteng | J32: Under warranty till 04-01-2026
B33: Yealink | C33: SIP-T31W | D33: Yealink T31W Desktop IP Phone With Built-In Wi-Fi, 10/100Mb Ethernet, Includes PSU | E33: 1 | F33: 940 | G33: 659 | H33: Available on request | I33: Gauteng | J33: Under warranty till 18-07-2026
B34: Yealink | C34: SIP-T33G | D34: Yealink SIP-T33G Gigabit Colour Screen Desktop IP Phone, Excludes PSU | E34: 10 | F34: 964 | G34: 759 | H34: Available on request | I34: Gauteng | J34: Warranty expired | K34: Add Nology BB Warranty-12
B35: Yealink | C35: SIP-T34W | D35: Yealink SIP-T34W Desktop IP Phone With Built-In Wi-Fi, Includes PSU | E35: 1 | F35: 1129 | G35: 789 | H35: Available on request | I35: Gauteng | J35: Warranty expired | K35: Add Nology BB Warranty-12
B36: Yealink | C36: SIP-T40P | D36: Yealink T40P Fe, Bw, IP Phone, Excludes PSU (EOL) | E36: 4 | F36: - | G36: 499 | H36: Available on request | I36: Gauteng | J36: Warranty expired | K36: Add Nology BB Warranty-12
B37: Yealink | C37: SIP-T46U | D37: Yealink T46U Gb IP Phone With Dual USB Ports And 4.3" Colour LCD, Excludes PSU | E37: 1 | F37: 2375 | G37: 1659 | H37: Available on request | I37: Gauteng | J37: Warranty expired | K37: Add Nology BB Warranty-12
B38: Yealink | C38: SIP-T48U | D38: Yealink T48U Gb IP Phone With 7" Touch LCD And Dual USB Ports, Excludes PSU (EOL) | E38: 1 | F38: 2849 | G38: 1999 | H38: Available on request | I38: Gauteng | J38: Warranty expired | K38: Add Nology BB Warranty-12
B39: Yealink | C39: SIP-T53W | D39: Yealink T53W Dual Band Wi-Fi IP Phone, Excludes PSU (EOL) | E39: 1 | F39: 2239 | G39: 1569 | H39: Available on request | I39: Gauteng | J39: Warranty expired | K39: Add Nology BB Warranty-12
B40: Yealink | C40: SIP-T57W | D40: Yealink T57W Dual Band IP Desktop Phone, Excludes PSU (EOL) | E40: 1 | F40: 3299 | G40: 2309 | H40: Available on request | I40: Gauteng | J40: Warranty expired | K40: Add Nology BB Warranty-12
B41: Yealink | C41: SIP-T58W | D41: Yealink T58W Smart Business Phone, Excl. Camera, Excl. PSU (EOL) | E41: 1 | F41: 5145 | G41: 3599 | H41: Available on request | I41: Gauteng | J41: Warranty expired
B42: Yealink | C42: UH34-LITE-DUAL | D42: Yealink UH34 Lite Dual Earpiece USB Headset With Foam Ear Cushions Teams Edition | E42: 3 | F42: 477 | G42: 329 | H42: Available on request | I42: Gauteng | J42: Warranty expired | K42: Add Nology BB Warranty-12
B43: Yealink | C43: W73P | D43: Yealink W73P IP DECT Phone And Base Station (Incl. W70B And W73H) | E43: 1 | F43: 1693 | G43: 1189 | H43: Available on request | I43: Gauteng | J43: Under warranty till 20-12-2024 | K43: Add Nology BB Warranty-12
B44: Yealink | C44: W78H | D44: Yealink W78H DECT Handset | E44: 1 | F44: 1552 | G44: 1089 | H44: Available on request | I44: Gauteng | J44: Warranty expired | K44: Add Nology BB Warranty-12
B45: Yealink | C45: W80B-DM | D45: Yealink W80B-DM Multi-Cell DECT Manager | E45: 1 | F45: 3293 | G45: 2309 | H45: Available on request | I45: Gauteng | J45: Warranty expired | K45: Add Nology BB Warranty-12
B46: Yealink | C46: WH66-DUAL | D46: Yealink WH66 Dual DECT Wireless On Ear Stereo Headset With Touch Screen Base Station | E46: 2 | F46: 3398 | G46: 2379 | H46: Available on request | I46: Gauteng | J46: Warranty expired | K46: Add Nology BB Warranty-12
...

Sheet 3CX
E1: Return
B3: * 3CX QUOTES ARE BASED ON THE FEC AVAILABLE * | D3: LIST PRICE - $ PRICE EXCLUDING PARTNER LEVEL DISCOUNT
B4: BASIC | D4: Annual | E4: Comments
B5: BAS-8SCAN | C5: 3CX Basic V20 8SC license | D5: 300 | E5: NEW
B6: BAS-16SCAN | C6: 3CX Basic V20 16SC license | D6: 600 | E6: NEW
B7: BAS-24SCAN | C7: 3CX Basic V20 24SC license | D7: 825 | E7: NEW
B8: BAS-32SCAN | C8: 3CX Basic V20 32SC license | D8: 1015 | E8: NEW
B9: BAS-48SCAN | C9: 3CX Basic V20 48SC license | D9: 1500 | E9: NEW
B10: BAS-64SCAN | C10: 3CX Basic V20 64SC license | D10: 2025 | E10: NEW
B11: BAS-96SCAN | C11: 3CX Basic V20 96SC license | D11: 3000 | E11: NEW
B12: BAS-128SCAN | C12: 3CX Basic V20 128SC license | D12: 4125 | E12: NEW
B13: BAS-192SCAN | C13: 3CX Basic V20 192SC license | D13: 6190 | E13: NEW
B14: BAS-256SCAN | C14: 3CX Basic V20 256SC license | D14: 8250 | E14: NEW
B15: BAS-512SCAN | C15: 3CX Basic V20 512SC license | D15: 13500 | E15: NEW
B16: BAS-1024SCAN | C16: 3CX Basic V20 1024SC license | D16: 24750 | E16: NEW
B17: PROFESSIONAL | D17: Annual | E17: Comments
B18: PRO-8SCAN | C18: 3CX Professional V20 8SC license | D18: 395
B19: PRO-16SCAN | C19: 3CX Professional V20 16SC license | D19: 795
B20: PRO-24SCAN | C20: 3CX Professional V20 24SC license | D20: 1095
B21: PRO-32SCAN | C21: 3CX Professional V20 32SC license | D21: 1350
B22: PRO-48SCAN | C22: 3CX Professional V20 48SC license | D22: 1995
B23: PRO-64SCAN | C23: 3CX Professional V20 64SC license | D23: 2695
B24: PRO-96SCAN | C24: 3CX Professional V20 96SC license | D24: 3995
B25: PRO-128SCAN | C25: 3CX Professional V20 128SC license | D25: 5495
B26: PRO-192SCAN | C26: 3CX Professional V20 192SC license | D26: 8250
B27: PRO-256SCAN | C27: 3CX Professional V20 256SC license | D27: 10995
B28: PRO-512SCAN | C28: 3CX Professional V20 512SC license | D28: 17995
B29: PRO-1024SCAN | C29: 3CX Professional V20 1024SC license | D29: 32995
B30: ENTERPRISE | D30: Annual | E30: Comments
B31: ENT-8SCAN | C31: 3CX Enterprise V20 8SC license | D31: 575
B32: ENT-16SCAN | C32: 3CX Enterprise V20 16SC license | D32: 1095
B33: ENT-24SCAN | C33: 3CX Enterprise V20 24SC license | D33: 1495
B34: ENT-32SCAN | C34: 3CX Enterprise V20 32C license | D34: 1795
B35: ENT-48SCAN | C35: 3CX Enterprise V20 48SC license | D35: 2495
B36: ENT-64SCAN | C36: 3CX Enterprise V20 64SC license | D36: 3235
B37: ENT-96SCAN | C37: 3CX Enterprise V20 96SC license | D37: 4795
B38: ENT-128SCAN | C38: 3CX Enterprise V20 128SC license | D38: 6595
B39: ENT-192SCAN | C39: 3CX Enterprise V20 192SC license | D39: 9900
B40: ENT-256-SCAN | C40: 3CX Enterprise V20 256SC license | D40: 13195
B41: ENT-512SCAN | C41: 3CX Enterprise V20 512SC license | D41: 21915
...

Sheet Apache Optics
E1: Return
B3: SKU | C3: DESCRIPTION | D3: PRICE | E3: COMMENTS
B4: APACHE OPTICS
B5: 1P-SFP1GESX | C5: Apache Optics 1G SFP - Multimode, 850nm, 550m reach, LC | D5: =INDEX(PRICING!AE:AE,MATCH(B5,PRICING!AD:AD,0),1) -> 431
B6: 1P-SFP1GELX | C6: Apache Optics 1G SFP - Single mode, 1310nm, 10km reach, LC | D6: =INDEX(PRICING!AE:AE,MATCH(B6,PRICING!AD:AD,0),1) -> 482
B7: 1P-SFP1GET | C7: Apache Optics 1000 baseT UTP SFP - RJ-45, 100m reach | D7: =INDEX(PRICING!AE:AE,MATCH(B7,PRICING!AD:AD,0),1) -> 1147
B8: 1P-SFP10GSR | C8: Apache Optics 10G SFP - Multimode, 850nm, 300m reach, LC | D8: =INDEX(PRICING!AE:AE,MATCH(B8,PRICING!AD:AD,0),1) -> 1017
B9: 1P-SFP10GLR | C9: Apache Optics 10G SFP - Single mode, 1310nm, 10km reach, LC | D9: =INDEX(PRICING!AE:AE,MATCH(B9,PRICING!AD:AD,0),1) -> 1448
B10: 1P-SFP10GUTP | C10: Apache Optics 10G UTP SFP - RJ-45, 100m reach | D10: =INDEX(PRICING!AE:AE,MATCH(B10,PRICING!AD:AD,0),1) -> 2954
B11: 1P-SFP25GSR | C11: Apache Optics 25G-SR SFP28 850nm 100m DOM Duplex LC MMF | D11: =INDEX(PRICING!AE:AE,MATCH(B11,PRICING!AD:AD,0),1) -> 1630
B12: 1P-SFP25GLR | C12: Apache Optics 25G-LR SFP28 1310nm 10km DOM Duplex LC SMF | D12: =INDEX(PRICING!AE:AE,MATCH(B12,PRICING!AD:AD,0),1) -> 2547
