Workbook

Sheet Progress
B1: Total | C1: Processed | D1: Difference | E1: Rate% | G1: 45548 | I1: OVERVIEW | J1: Agents tasked to assist | K1: Total | L1: Processed | M1: Difference | N1: Rate%
A2: Clients (A - D) | B2: ='Clients (A - D)'!B1 -> 3294 | C2: =COUNTIFS('Clients (A - D)'!A$4:A1003,$A1,'Clients (A - D)'!C$4:C1003,"?*") -> 0 | D2: =B2-C2 -> 3294 | E2: =C2/B2 -> 0 | G2: 120 | I2: Clients (A - D) | J2: Marisa + Darne | K2: ='Clients (A - D)'!B1 -> 3294 | L2: ='Clients (A - D)'!C1 -> 645 | M2: =K2-L2 -> 2649 | N2: =L2/K2 -> 0.19581056
A3: Clients (E - H) | B3: ='Clients (E - H)'!B1 -> 1532 | C3: =COUNTIFS('Clients (E - H)'!A$4:A1003,$A1,'Clients (E - H)'!C$4:C1003,"?*") -> 0 | D3: =B3-C3 -> 1532 | E3: =C3/B3 -> 0 | G3: 76 | I3: Clients (E - H) | J3: Farren | K3: ='Clients (E - H)'!B1 -> 1532 | L3: ='Clients (E - H)'!C1 -> 159 | M3: =K3-L3 -> 1373 | N3: =L3/K3 -> 0.1037859
A4: Clients (I - L) | B4: ='Clients (I - L)'!B1 -> 1814 | C4: =COUNTIFS('Clients (I - L)'!A$4:A1003,$A1,'Clients (I - L)'!C$4:C1003,"?*") -> 0 | D4: =B4-C4 -> 1814 | E4: =C4/B4 -> 0 | G4: 52 | I4: Clients (I - L) | J4: Larinda + Kayla | K4: ='Clients (I - L)'!B1 -> 1814 | L4: ='Clients (I - L)'!C1 -> 1076 | M4: =K4-L4 -> 738 | N4: =L4/K4 -> 0.59316428
A5: Clients (M - P) | B5: ='Clients (M - P)'!B1 -> 2150 | C5: =COUNTIFS('Clients (M - P)'!A$4:A1003,$A1,'Clients (M - P)'!C$4:C1003,"?*") -> 0 | D5: =B5-C5 -> 2150 | E5: =C5/B5 -> 0 | G5: 64 | I5: Clients (M - P) | J5: Jessica | K5: ='Clients (M - P)'!B1 -> 2150 | L5: ='Clients (M - P)'!C1 -> 1239 | M5: =K5-L5 -> 911 | N5: =L5/K5 -> 0.57627907
A6: Clients (Q - T) | B6: ='Clients (Q - T)'!B1 -> 1974 | C6: =COUNTIFS('Clients (Q - T)'!A$4:A1003,$A1,'Clients (Q - T)'!C$4:C1003,"?*") -> 0 | D6: =B6-C6 -> 1974 | E6: =C6/B6 -> 0 | G6: 3 | I6: Clients (Q - T) | J6: Ryanicea & Adele | K6: ='Clients (Q - T)'!B1 -> 1974 | L6: ='Clients (Q - T)'!C1 -> 1033 | M6: =K6-L6 -> 941 | N6: =L6/K6 -> 0.52330294
A7: Clients (U - V) | B7: ='Clients (U - V)'!B1 -> 1101 | C7: =COUNTIFS('Clients (U - V)'!A$4:A1003,$A1,'Clients (U - V)'!C$4:C1003,"?*") -> 0 | D7: =B7-C7 -> 1101 | E7: =C7/B7 -> 0 | G7: 29 | I7: Clients (U - V) | J7: Charlize | K7: ='Clients (U - V)'!B1 -> 1101 | L7: ='Clients (U - V)'!C1 -> 117 | M7: =K7-L7 -> 984 | N7: =L7/K7 -> 0.10626703
A8: Clients (W - Z) | B8: ='Clients (W - Z)'!B1 -> 556 | C8: =COUNTIFS('Clients (W - Z)'!A$4:A1003,$A1,'Clients (W - Z)'!C$4:C1003,"?*") -> 0 | D8: =B8-C8 -> 556 | E8: =C8/B8 -> 0 | G8: 76 | I8: Clients (W - Z) | J8: Cassidy | K8: ='Clients (W - Z)'!B1 -> 556 | L8: ='Clients (W - Z)'!C1 -> 378 | M8: =K8-L8 -> 178 | N8: =L8/K8 -> 0.67985612
B10: =SUM(B2:B8) -> 12421 | C10: =SUM(C2:C8) -> 0 | D10: =SUM(D2:D8) -> 12421 | E10: =C10/B10 -> 0 | K10: =SUM(K2:K8) -> 12421 | L10: =SUM(L2:L8) -> 4647 | M10: =SUM(M2:M8) -> 7774 | N10: =L10/K10 -> 0.37412447
B12: =SUM(B2:B8) -> 12421 | C12: =SUM(C2:C8) -> 0 | D12: =SUM(D2:D8) -> 12421 | E12: =C12/B12 -> 0
A13: 45551 | B13: Total | C13: Processed | D13: Difference | E13: Rate% | G13: 45551
A14: Clients (A - D) | B14: =D2 -> 3294 | C14: =COUNTIFS('Clients (A - D)'!A$4:A1003,$A13,'Clients (A - D)'!C$4:C1003,"?*") -> 0 | D14: =B14-C14 -> 3294 | E14: =C14/B14 -> 0 | G14: 124
A15: Clients (E - H) | B15: =D3 -> 1532 | C15: =COUNTIFS('Clients (E - H)'!A$4:A1003,$A13,'Clients (E - H)'!C$4:C1003,"?*") -> 0 | D15: =B15-C15 -> 1532 | E15: =C15/B15 -> 0 | G15: 125
A16: Clients (I - L) | B16: =D4 -> 1814 | C16: =COUNTIFS('Clients (I - L)'!A$4:A1003,$A13,'Clients (I - L)'!C$4:C1003,"?*") -> 0 | D16: =B16-C16 -> 1814 | E16: =C16/B16 -> 0 | G16: 52
A17: Clients (M - P) | B17: =D5 -> 2150 | C17: =COUNTIFS('Clients (M - P)'!A$4:A1003,$A13,'Clients (M - P)'!C$4:C1003,"?*") -> 9 | D17: =B17-C17 -> 2141 | E17: =C17/B17 -> 0.0041860465 | G17: 64
A18: Clients (Q - T) | B18: =D6 -> 1974 | C18: =COUNTIFS('Clients (Q - T)'!A$4:A1003,$A13,'Clients (Q - T)'!C$4:C1003,"?*") -> 0 | D18: =B18-C18 -> 1974 | E18: =C18/B18 -> 0 | G18: 8
A19: Clients (U - V) | B19: =D7 -> 1101 | C19: =COUNTIFS('Clients (U - V)'!A$4:A1003,$A13,'Clients (U - V)'!C$4:C1003,"?*") -> 0 | D19: =B19-C19 -> 1101 | E19: =C19/B19 -> 0 | G19: 30
A20: Clients (W - Z) | B20: =D8 -> 556 | C20: =COUNTIFS('Clients (W - Z)'!A$4:A1003,$A13,'Clients (W - Z)'!C$4:C1003,"?*") -> 0 | D20: =B20-C20 -> 556 | E20: =C20/B20 -> 0 | G20: 98
B22: =SUM(B14:B20) -> 12421 | C22: =SUM(C14:C20) -> 9 | D22: =SUM(D14:D20) -> 12412 | E22: =C22/B22 -> 0.00072457934
A24: 45552 | B24: Total | C24: Processed | D24: Difference | E24: Rate% | G24: 45552
A25: Clients (A - D) | B25: =D14 -> 3294 | C25: =COUNTIFS('Clients (A - D)'!A$4:A1003,$A24,'Clients (A - D)'!C$4:C1003,"?*") -> 0 | D25: =B25-C25 -> 3294 | E25: =C25/B25 -> 0 | G25: 124
A26: Clients (E - H) | B26: =D15 -> 1532 | C26: =COUNTIFS('Clients (E - H)'!A$4:A1003,$A24,'Clients (E - H)'!C$4:C1003,"?*") -> 0 | D26: =B26-C26 -> 1532 | E26: =C26/B26 -> 0 | G26: 141
A27: Clients (I - L) | B27: =D16 -> 1814 | C27: =COUNTIFS('Clients (I - L)'!A$4:A1003,$A24,'Clients (I - L)'!C$4:C1003,"?*") -> 0 | D27: =B27-C27 -> 1814 | E27: =C27/B27 -> 0 | G27: 52
A28: Clients (M - P) | B28: =D17 -> 2141 | C28: =COUNTIFS('Clients (M - P)'!A$4:A1003,$A24,'Clients (M - P)'!C$4:C1003,"?*") -> 102 | D28: =B28-C28 -> 2039 | E28: =C28/B28 -> 0.047641289 | G28: 117
A29: Clients (Q - T) | B29: =D18 -> 1974 | C29: =COUNTIFS('Clients (Q - T)'!A$4:A1003,$A24,'Clients (Q - T)'!C$4:C1003,"?*") -> 0 | D29: =B29-C29 -> 1974 | E29: =C29/B29 -> 0 | G29: 28
A30: Clients (U - V) | B30: =D19 -> 1101 | C30: =COUNTIFS('Clients (U - V)'!A$4:A1003,$A24,'Clients (U - V)'!C$4:C1003,"?*") -> 0 | D30: =B30-C30 -> 1101 | E30: =C30/B30 -> 0 | G30: 30
A31: Clients (W - Z) | B31: =D20 -> 556 | C31: =COUNTIFS('Clients (W - Z)'!A$4:A1003,$A24,'Clients (W - Z)'!C$4:C1003,"?*") -> 0 | D31: =B31-C31 -> 556 | E31: =C31/B31 -> 0 | G31: 98
B33: =SUM(B25:B31) -> 12412 | C33: =SUM(C25:C31) -> 102 | D33: =SUM(D25:D31) -> 12310 | E33: =C33/B33 -> 0.0082178537
A35: 45553 | B35: Total | C35: Processed | D35: Difference | E35: Rate% | G35: 45553
A36: Clients (A - D) | B36: =D25 -> 3294 | C36: =COUNTIFS('Clients (A - D)'!A$4:A1003,$A35,'Clients (A - D)'!C$4:C1003,"?*") -> 73 | D36: =B36-C36 -> 3221 | E36: =C36/B36 -> 0.022161506 | G36: 166
A37: Clients (E - H) | B37: =D26 -> 1532 | C37: =COUNTIFS('Clients (E - H)'!A$4:A1003,$A35,'Clients (E - H)'!C$4:C1003,"?*") -> 0 | D37: =B37-C37 -> 1532 | E37: =C37/B37 -> 0 | G37: 144
A38: Clients (I - L) | B38: =D27 -> 1814 | C38: =COUNTIFS('Clients (I - L)'!A$4:A1003,$A35,'Clients (I - L)'!C$4:C1003,"?*") -> 58 | D38: =B38-C38 -> 1756 | E38: =C38/B38 -> 0.031973539 | G38: 53
A39: Clients (M - P) | B39: =D28 -> 2039 | C39: =COUNTIFS('Clients (M - P)'!A$4:A1003,$A35,'Clients (M - P)'!C$4:C1003,"?*") -> 0 | D39: =B39-C39 -> 2039 | E39: =C39/B39 -> 0 | G39: 186
A40: Clients (Q - T) | B40: =D29 -> 1974 | C40: =COUNTIFS('Clients (Q - T)'!A$4:A1003,$A35,'Clients (Q - T)'!C$4:C1003,"?*") -> 0 | D40: =B40-C40 -> 1974 | E40: =C40/B40 -> 0 | G40: 57
A41: Clients (U - V) | B41: =D30 -> 1101 | C41: =COUNTIFS('Clients (U - V)'!A$4:A1003,$A35,'Clients (U - V)'!C$4:C1003,"?*") -> 0 | D41: =B41-C41 -> 1101 | E41: =C41/B41 -> 0 | G41: 37
A42: Clients (W - Z) | B42: =D31 -> 556 | C42: =COUNTIFS('Clients (W - Z)'!A$4:A1003,$A35,'Clients (W - Z)'!C$4:C1003,"?*") -> 20 | D42: =B42-C42 -> 536 | E42: =C42/B42 -> 0.035971223 | G42: 98
B43: =D32 -> 0
B44: =SUM(B36:B42) -> 12310 | C44: =SUM(C36:C42) -> 151 | D44: =SUM(D36:D42) -> 12159 | E44: =C44/B44 -> 0.01226645
A46: 45554 | B46: Total | C46: Processed | D46: Difference | E46: Rate% | G46: 45554
A47: Clients (A - D) | B47: =D36 -> 3221 | C47: =COUNTIFS('Clients (A - D)'!A$4:A1003,$A46,'Clients (A - D)'!C$4:C1003,"?*") -> 0 | D47: =B47-C47 -> 3221 | E47: =C47/B47 -> 0 | G47: 240
...

Sheet Clients (A - D)
B1: =COUNTA(B4:B3298) -> 3294 | C1: =COUNTIF(C4:C3298,"?*") -> 645
A2: Date | B2: Client Account | C2: Client Reference | D2: Client name | E2: Highsite / SC | F2: Type | G2: ISPMan Premium | H2: ISPMan EFT Fee | I2: Contract Duration | J2: Install Date | K2: Contract Expiry | L2: Have Contract | M2: Notes
B3: ABC001 | C3: ABC001-12345 | D3: Mr Joe Soap | E3: Dwarskersbos S/C | F3: Trusc Wireless | I3: 1 Year | K3: 45626 | L3: TRUE | M3: Example line
A4: 45548 | B4: AAD001 | C4: AAD001-11532 | D4: AA Aadan | E4: Oranjefontein | F4: Trusc Wireless | G4: 344 | H4: 35 | I4: 2 year | J4: 44900 | K4: 46361 | L4: TRUE
A5: 45548 | B5: AAL001 | C5: AAL001-13068 | D5: F Aaltge | E5: Koringberg | F5: Trusc Wireless | G5: 574 | H5: 0 | I5: 2 year | J5: 44606 | K5: 45336 | L5: TRUE
A6: 45548 | B6: AAN001 | C6: AAN001-5829 | D6: Aands Managed Services | E6: Dwarskersbos S/C | F6: Trusc Wireless | G6: 574 | H6: 0 | I6: 2 year | J6: 44168 | K6: 44898 | L6: TRUE
A7: 45548 | B7: AAR001 | C7: AAR001-23350 | D7: Aardwolf Security Solution (PTY) Ltd | E7: None | F7: Trusc Fibre | G7: 399 | H7: 58 | I7: 2 year | J7: 45182 | K7: 45913 | L7: TRUE
A8: 45548 | B8: ABA003 | C8: ABA003-7674 | D8: NT Abata | E8: Windpomp | F8: Trusc Wireless | G8: 298 | H8: 0 | I8: 2 year | J8: 43701 | K8: 44432 | L8: TRUE
A9: 45548 | B9: ABB004 | C9: ABB004-22168 | D9: B Abbott | E9: Bulshoek | F9: Trusc Wireless | G9: 574 | H9: 0 | I9: 2 year | J9: 44988 | K9: 45719 | L9: TRUE
A10: 45548 | B10: ABC001 | C10: ABC001-18852 | D10: ABCO Ingenieurs Werke (Edms) Bpk | E10: None | F10: Openserve | G10: 1375 | H10: 0 | I10: 2 year | J10: 44712 | K10: 45443 | L10: TRUE
A11: 45548 | B11: ABC001 | C11: ABC001-5746 | D11: ABCO Ingenieurs Werke (Edms) Bpk | E11: Springbok | F11: Trusc Wireless | G11: 1609 | H11: 0 | I11: 2 year | J11: 43399 | K11: 44130 | L11: TRUE
A12: 45548 | B12: ABD002 | C12: ABD002-4931 | D12: LS Abdol | E12: Koraan | F12: Trusc Wireless | G12: 574 | H12: 0 | I12: 2 year | J12: 44110 | K12: 44840 | L12: TRUE
A13: 45548 | B13: ABD005 | C13: ABD005-7802 | D13: AM Abdulahi | E13: Clan | F13: Trusc Wireless | G13: 459 | H13: 0 | I13: 2 year | J13: 43728 | K13: 44459 | L13: TRUE
A14: 45548 | B14: ABD005 | C14: ABD005-9116 | D14: AM Abdulahi | E14: Synott | F14: Trusc Wireless | G14: 459 | H14: 0 | I14: 2 year | J14: 43879 | K14: 44610 | L14: TRUE
A15: 45548 | B15: ABD009 | C15: ABD009-8564 | D15: WC Abdol | E15: Koraan | F15: Trusc Wireless | G15: 350 | H15: 35 | I15: 2 year | J15: 45243 | K15: 45974 | L15: TRUE
... A50: 45548 | B50: ABR064 | C50: ABR064-20558 | D50: I Abrahams | E50: None | F50: Trusc Fibre | G50: 344 | H50: 0 | I50: 2 year | J50: 44856 | K50: 45587 | L50: TRUE
A51: 45548 | B51: ABR065 | C51: ABR065-21098 | D51: JW Abrahams | E51: Klawer-Res | F51: Trusc Wireless | G51: 574 | H51: 0 | I51: 2 year | J51: To be processed | K51: To be processed | L51: TRUE
A52: 45548 | B52: ABR066 | C52: ABR066-21260 | D52: NJP Abrahams | E52: Klawer-Res | F52: Trusc Wireless | G52: 574 | H52: 0 | I52: 2 year | J52: 44904 | K52: 45635 | L52: TRUE
A53: 45548 | B53: ABR069 | C53: ABR069-21477 | D53: RB Abrahams | E53: Modderfontein | F53: Trusc Wireless | G53: 574 | H53: 0 | I53: 2 year | J53: 44925 | K53: 45656 | L53: TRUE
A54: 45548 | B54: ABR074 | C54: ABR074-22847 | D54: DD Abrahams | E54: Piketberg | F54: Trusc Wireless | G54: 344 | H54: 0 | I54: 2 year | J54: 45343 | K54: 46074 | L54: TRUE
A55: 45548 | B55: ABR075 | C55: ABR075-23073 | D55: TI Abrahams | E55: Paardeberg | F55: Trusc Wireless | G55: 344 | H55: 35 | I55: 2 year | J55: 45119 | K55: 45850 | L55: TRUE
A56: 45548 | B56: ABR076 | C56: ABR076-23099 | D56: BB Abrahams | E56: Okiep | F56: Trusc Wireless | G56: 344 | H56: 0 | I56: 2 year | J56: 45124 | K56: 45856 | L56: TRUE
A57: 45548 | B57: ABR077 | C57: ABR077-23133 | D57: MB Abrahamse | E57: None | F57: Trusc Fibre | G57: 344 | H57: 0 | I57: 2 year | J57: 45129 | K57: 45860 | L57: TRUE
A58: 45548 | B58: ABR078 | C58: ABR078-23163 | D58: P Abrahams | E58: Koringberg | F58: Trusc Wireless | G58: 574 | H58: 0 | I58: 2 year | J58: 45132 | K58: 45863 | L58: TRUE
A59: 45548 | B59: ABR080 | C59: ABR080-23741 | D59: ZL Abrahams | E59: Heuningberg | F59: Trusc Wireless | G59: 350 | H59: 0 | I59: 2 year | J59: 45206 | K59: 45937 | L59: TRUE
A60: 45548 | B60: ABR083 | C60: ABR083-24481 | D60: AG Abrahams | E60: Doornbaai | F60: Trusc Wireless | G60: 350 | H60: 0 | I60: 2 year | J60: 45262 | K60: 45993 | L60: TRUE
A61: 45548 | B61: ABR084 | C61: ABR084-24887 | D61: B Abrahams | E61: Klawer | F61: Trusc Wireless | G61: 350 | H61: 0 | I61: 2 year | J61: 45307 | K61: 46038 | L61: TRUE
A62: 45548 | B62: ABR085 | C62: ABR085-25059 | D62: CA Abrahams | E62: Aurora | F62: Trusc Wireless | G62: 350 | H62: 0 | I62: 2 year | J62: 45315 | K62: 46046 | L62: TRUE
A63: 45548 | B63: ABR086 | C63: ABR086-25142 | D63: WZ Abrahams | E63: Oranjefontein | F63: Trusc Wireless | G63: 350 | H63: 0 | I63: 2 year | J63: 45323 | K63: 46054 | L63: TRUE
... A68: 45548 | B68: ABR092 | C68: ABR092-27488 | D68: MEJ Abrahams | E68: Graafwater | F68: Trusc Wireless | G68: 299 | H68: 0 | I68: 2 year | J68: 45505 | K68: 46235 | L68: TRUE
A69: 45548 | B69: ABR093 | C69: ABR093-27693 | D69: R Abrahams | E69: Kalbaskraal | F69: Trusc Wireless | G69: 299 | H69: 0 | I69: 2 year | J69: 45534 | K69: 46264 | L69: TRUE | M69: Still to be installed
A70: 45548 | B70: ABR094 | C70: ABR094-27823 | D70: H Abrahams | E70: Doornbaai | F70: Trusc Wireless | G70: 299 | H70: 0 | I70: 2 year | J70: 45169 | K70: 45900 | L70: TRUE
A71: 45548 | B71: ABR095 | C71: ABR095-27849 | D71: S Abrahams | E71: Synott | F71: Trusc Wireless | G71: 299 | H71: 0 | I71: 2 year | J71: 45168 | K71: 45899 | L71: TRUE
A72: 45548 | B72: ABS002 | C72: ABS002-19999 | D72: AM Absolon | E72: Piketberg | F72: Trusc Wireless | G72: 574 | H72: 0 | I72: 2 year | J72: 44810 | K72: 45541 | L72: TRUE
A73: 45553 | B73: ABS003 | C73: ABS003-27884 | D73: AE Absolom | E73: Steelwater | F73: Trusc Wireless | G73: 299 | H73: 0 | I73: 2 year | J73: 45542 | K73: 46272 | L73: TRUE
A74: 45548 | B74: ACA001 | C74: ACA001-15428 | D74: Academy of Diving and Offshore Medicine PTY Ltd | E74: Masada | F74: Trusc Wireless | G74: 977 | H74: 0 | I74: 2 year | J74: 44454 | K74: 45184 | L74: TRUE
A75: 45548 | B75: ACA002 | C75: ACA002-26022 | D75: Acacia Marketing | E75: Dwarskersbos S/C | F75: Trusc Fibre | G75: 399 | H75: 0 | I75: 2 year | J75: 45393 | K75: 46123 | L75: TRUE
A76: 45548 | B76: ACH003 | C76: ACH003-13776 | D76: CA Achilles | E76: Tallie Marine | F76: Trusc Wireless | G76: 402 | H76: 0 | J76: 44377 | L76: FALSE | M76: No signed SLA
A77: 45548 | B77: ACH006 | C77: ACH006-17019 | D77: TC Achilles | E77: Tallie Marine | F77: Trusc Wireless | G77: 402 | H77: 0 | I77: 2 year | J77: 44548 | K77: 45278 | L77: TRUE
A78: 45548 | B78: ACK006 | C78: ACK006-18736 | D78: PL Ackeer | E78: Duiwelskop | F78: Trusc Wireless | G78: 574 | H78: 0 | I78: 2 year | J78: 44691 | K78: 45422 | L78: TRUE
...

Sheet Clients (E - H)
B1: =COUNTA(B4:B1535) -> 1532 | C1: =COUNTIF(C4:C1535,"?*") -> 159
A2: Date | B2: Client Account | C2: Client Reference | D2: Client name | E2: Highsite / SC | F2: Type | G2: ISPMan Premium | H2: ISPMan EFT Fee | I2: Contract Duration | J2: Install Date | K2: Contract Expiry | L2: Have Contract
B3: ABC001 | C3: ABC001-12345 | D3: Mr Joe Soap | E3: Dwarskersbos S/C | F3: Trusc Wireless | I3: 1 Year | K3: 45626 | L3: TRUE | M3: Example line
A4: 45548 | B4: EAL001 | C4: EAL001-24642 | D4: EA Lombard Family Trust ta | E4: Strand | F4: Trusc Wireless | G4: 350 | H4: 0 | I4: 2 year | J4: 45279 | K4: 46023 | L4: TRUE
A5: 45548 | B5: EAR002 | C5: EAR002-15529 | D5: Earth Hero Movement NPC | E5: vlan179 | F5: Trusc Wireless | G5: 1149 | H5: 0 | I5: 2 year | J5: 44858 | K5: 45597 | L5: TRUE
A6: 45548 | B6: EAS001 | C6: EAS001-17797 | D6: Easygram CC t/a Easygram Telegram Services | E6: Aasvoelkop-aasvoelkop-switch1 | F6: Openserve | G6: 699 | H6: 0 | I6: 2 year | J6: 45271 | K6: 46003 | L6: TRUE
A7: 45548 | B7: EBE001 | C7: EBE001-1274 | D7: Ebenhaeser VGK | E7: Eben | F7: Trusc Wireless | G7: 344 | H7: 0 | I7: 2 year | J7: 44947 | K7: 45689 | L7: TRUE
A8: 45548 | B8: EBE003 | C8: EBE003-16720 | D8: Ebenhaezer Primary School | E8: ebenheazer-apa11 | F8: Trusc Wireless | G8: 0 | H8: 0 | I8: Sponsorship Agreement | J8: 44616 | K8: 45261 | L8: TRUE
A9: 45548 | B9: EBE005 | C9: EBE005-26157 | D9: WJ Ebersohn | E9: vdal_north-apa2 | F9: Trusc Wireless | G9: 350 | H9: 35 | I9: 2 year | J9: 45406 | K9: 46143 | L9: TRUE
A10: 45548 | B10: EBI003 | C10: EBI003-11327 | D10: JL Ebing | E10: rooidraai-apa12 | F10: Trusc Wireless | G10: 804 | H10: 0 | I10: 2 year | J10: 44132 | K10: 44866 | L10: TRUE
A11: 45548 | B11: EBI004 | C11: EBI004-11354 | D11: JL Ebing | E11: rooidraai-apa18 | F11: Trusc Wireless | G11: 804 | H11: 0 | I11: 2 year | J11: 44959 | K11: 45717 | L11: TRUE
A12: 45548 | B12: EBS002 | C12: EBS002-5429 | D12: EBS Civils CC | E12: langebaan-apa14 | F12: Trusc Wireless | G12: 0 | H12: 0 | I12: 2 year | J12: 45051 | K12: 45809 | L12: TRUE
A13: 45548 | B13: ECK002 | C13: ECK002-27590 | D13: L Eckardt | E13: Aasvoelkop-aasvoelkop-switch1 | F13: Trusc Wireless | G13: 350 | H13: 0 | I13: 2 year | J13: Still need to Install | K13: 45495 | L13: TRUE
A14: 45548 | B14: EDA003 | C14: EDA003-14380 | D14: MR Edas | E14: meisies_koshuis-apa1 | F14: Trusc Wireless | G14: 574 | H14: 0 | I14: 2 year | J14: 44404 | K14: 45139 | L14: TRUE
A15: 45548 | B15: EDA004 | C15: EDA004-27611 | D15: E Edas | E15: Aasvoelkop-aasvoelkop-switch1 | F15: Openserve | G15: 599 | H15: 0 | I15: 2 year | J15: 45497 | K15: 46227 | L15: TRUE
A16: 45548 | B16: EDA005 | C16: EDA005-16368 | D16: CJ Edas | E16: meisies_koshuis-apa1 | F16: Trusc Wireless | G16: 574 | H16: 0 | I16: 2 year | J16: 44524 | K16: 45261 | L16: TRUE
A17: 45548 | B17: EDA006 | C17: EDA006-19535 | D17: JS Edas | E17: oranjefontein-apa14 | F17: Trusc Wireless | G17: 574 | H17: 0 | I17: 2 year | J17: 44765 | K17: 45505 | L17: TRUE
A18: 45548 | B18: EDE002 | C18: EDE002-20096 | D18: Eden Primary School | E18: ether3 - lm_bakwerke-apa24 | F18: Trusc Wireless | G18: 0 | H18: 0 | I18: Sponsorship Agreement | J18: 44813 | K18: 45536 | L18: TRUE
A19: 45548 | B19: EDR001 | C19: EDR001-16862 | D19: MR Edries | E19: oranjefontein-apa7 | F19: Trusc Wireless | G19: 599 | H19: 0 | I19: 2 year | J19: 45520 | K19: 46250 | L19: TRUE
A20: 45548 | B20: EDW002 | C20: EDW002-10905 | D20: B Edwards | E20: wittedrift-apa4 | F20: Trusc Wireless | G20: 804 | H20: 0 | I20: 2 year | J20: 44076 | K20: 44805 | L20: TRUE
A21: 45548 | B21: EDW003 | C21: EDW003-11378 | D21: RG Edwards | E21: olifantskop-apa1 | F21: Trusc Wireless | G21: 574 | H21: 0 | I21: 2 year | J21: 44148 | K21: 44866 | L21: TRUE
A22: 45548 | B22: EEN001 | C22: EEN001-25581 | D22: Eensgezind Boerdery | E22: koringberg-apa14 | F22: Trusc Wireless | G22: 350 | H22: 0 | I22: 2 year | J22: 45357 | K22: 46068 | L22: TRUE
A23: 45548 | B23: EFF002 | C23: EFF002-8755 | D23: Effective Human Intervention PTY Ltd | E23: rilau-apa11 | F23: Trusc Wireless | G23: 689 | H23: 0 | I23: 2 year | J23: 43469 | K23: 44531 | L23: TRUE
A24: 45548 | B24: EFR001 | C24: EFR001-6488 | D24: L Efraim | E24: rooidraai-apa20 | F24: Trusc Wireless | G24: 350 | H24: 35 | I24: 2 year | J24: 45209 | K24: 45962 | L24: TRUE
A25: 45548 | B25: EGL001 | C25: EGL001-6038 | D25: W Egli | E25: eagle-apa1 | F25: Trusc Wireless | G25: 632 | H25: 0 | I25: 2 year | J25: 43524 | K25: 44228 | L25: TRUE
... A79: 45548 | B79: ENG003 | C79: ENG003-1588 | D79: JA Engelbrecht | E79: kapel-apa1 | F79: Trusc Wireless | G79: 574 | H79: 0 | I79: 2 year | J79: 44423 | K79: 45170 | L79: TRUE
B80: ENG009 | C80: ENG009-758 | D80: JHA Engelbrecht | E80: retshof-apa6 | F80: Trusc Wireless | G80: 574 | H80: 0 | I80: 2 year | J80: 44105 | K80: 44835 | L80: TRUE
B81: ENG013 | C81: ENG013-20158 | D81: JA Engelbrecht | E81: Vredendal-exchange-vredex-acc-switch1 | F81: Trusc Fibre | G81: 574 | H81: 0 | I81: 2 year | J81: 44849 | K81: 45566 | L81: TRUE
B82: ENG014 | C82: ENG014-1029 | D82: JF Engelbrecht | E82: lang-apa6 | F82: Trusc Wireless | G82: 299 | H82: 0 | I82: 2 year | J82: 45524 | K82: 46255 | L82: TRUE
B83: ENG014 | C83: ENG014-2221 | D83: JF Engelbrecht | E83: Lambertsbay | F83: Trusc Wireless | G83: 299 | H83: 0 | I83: 2 year | J83: 45532 | K83: 46255 | L83: TRUE
B84: ENG015 | C84: ENG015-1190 | D84: JC Engelbrecht | E84: rooirand-apa6 | F84: Trusc Wireless | G84: 804 | H84: 0 | I84: 2 year | J84: 45126 | K84: 45839 | L84: TRUE
B85: ENG023 | C85: ENG023-1565 | D85: SA Engelbrecht | E85: kapel_rep-apa1 | F85: Trusc Wireless | G85: 1149 | H85: 0 | I85: 2 year | J85: 44055 | K85: 44805 | L85: TRUE
B86: ENG023 | C86: ENG023-1580 | D86: SA Engelbrecht | E86: kapel_repeater | F86: Trusc Wireless | G86: 632 | H86: 0 | I86: 2 year | J86: 42761 | K86: 44805 | L86: TRUE
B87: ENG027 | C87: ENG027-1761 | D87: FC Engelbrecht | E87: koekrep-apa2 | F87: Trusc Wireless | G87: 402 | H87: 0 | I87: 2 year | J87: 43536 | K87: 44287 | L87: TRUE
B88: ENG028 | C88: ENG028-1941 | D88: HB Engelbrecht | E88: steelwater-apa5 | F88: Trusc Wireless | G88: 632 | H88: 35 | I88: 2 year | J88: 43263 | K88: 46059 | L88: TRUE
B89: ENG028 | C89: ENG028-5286 | D89: HB Engelbrecht | E89: steelwater-apa5 | F89: Trusc Wireless | G89: 350 | H89: 35 | I89: 2 year | J89: 45327 | K89: 46059 | L89: TRUE
B90: ENG035 | C90: ENG035-2453 | D90: AF Engelbrecht | E90: kransvlei-apa1 | F90: Trusc Wireless | G90: 699 | H90: 0 | I90: 2 year | J90: 45302 | K90: 46033 | L90: TRUE
B91: ENG043 | C91: ENG043-3581 | D91: AJ Engelbrecht | E91: lutzville-apa11 | F91: Trusc Wireless | G91: 574 | H91: 0 | I91: 2 year | J91: 44167 | K91: 44531 | L91: TRUE
B92: ENG045 | C92: ENG045-20924 | D92: N Engelbrecht | E92: Aasvoelkop-aasvoelkop-switch1 | F92: Trusc Fibre | G92: 0 | H92: 0 | I92: 2 year | J92: Still need to Install | K92: 45627 | L92: TRUE
B93: ENG045 | C93: ENG045-3912 | D93: N Engelbrecht | E93: watertower-apa1 | F93: Trusc Wireless | G93: 574 | H93: 0 | I93: 2 year | J93: 43894 | K93: 45627 | L93: TRUE
...

Sheet Clients (I - L)
B1: =COUNTA(B4:B3290) -> 1814 | C1: =COUNTIF(C4:C3290,"?*") -> 1076
A2: Date | B2: Client Account | C2: Client Reference | D2: Client name | E2: Highsite / SC | F2: Type | G2: ISPMan Premium | H2: ISPMan EFT Fee | I2: Contract Duration | J2: Install Date | K2: Contract Expiry | L2: Have Contract
B3: ABC001 | C3: ABC001-12345 | D3: Mr Joe Soap | E3: Dwarskersbos S/C | F3: Trusc Wireless | I3: 1 Year | K3: 45626 | L3: TRUE | M3: Example line
A4: 45548 | B4: IBG001 | C4: IBG001-22189 | D4: IBG Sureinvest An Independant Group cc | E4: Admiral Island | F4: Trusc Fibre | G4: 799 | H4: 0 | I4: 2 year | J4: 45022 | K4: 45753 | L4: TRUE
A5: 45548 | B5: IBR001 | C5: IBR001-5680 | D5: SJ Ibrahim | E5: vdal_north-apa5 | F5: Trusc Wireless | G5: 350 | H5: 35 | I5: 2 year | J5: 44867 | K5: 45598 | L5: TRUE
A6: 45548 | B6: IBR001 | C6: IBR001-24701 | D6: SJ Ibrahim | E6: vdal_res-apa14_c | F6: Trusc Wireless | G6: 350 | H6: 35 | I6: 2 year | J6: 45284 | K6: 46015 | L6: TRUE
A7: 45548 | B7: ICE001 | C7: ICE001-26438 | D7: SS Burger | E7: Dwarskersbos S/C | F7: Trusc Fibre | G7: 599 | H7: 0 | I7: 2 year | J7: 45409 | K7: 46139 | L7: FALSE | M7: no signed SLA for Fibre
A8: 45548 | B8: IGN001 | C8: - | D8: Ignite | G8: - | H8: - | L8: FALSE
A9: 45548 | B9: IKA002 | C9: IKA002-14573 | D9: C Ikaneng | E9: voorberg-apa6 | F9: Trusc Wireless | G9: 349 | H9: 0 | I9: 2 year | J9: 45442 | K9: 46172 | L9: TRUE
A10: 45548 | B10: ILL001 | C10: ILL001-11233 | D10: Ilingelethu Secondary School | E10: vlan109_oranjefontein-ap10_C-ppp | F10: Trusc Wireless | G10: 0 | H10: 0 | J10: 44138 | K10: 44868 | L10: FALSE
A11: 45548 | B11: IMA001 | C11: IMA001-23541 | D11: SI Iman | E11: malms_gh-apa4 | F11: Trusc Wireless | G11: 350 | H11: 35 | I11: 2 year | J11: 45189 | K11: 45920 | L11: TRUE
A12: 45548 | B12: IMI001 | C12: IMI001-12140 | D12: Imibala Orchards | E12: Heuningberg | F12: Trusc Wireless | G12: 977 | H12: 0 | I12: 2 year | J12: 44210 | K12: 44940 | L12: TRUE
A13: 45548 | B13: IMM002 | C13: IMM002-3115 | D13: GC Immelman | E13: kapel | F13: Trusc Wireless | G13: 599 | H13: 0 | I13: 2 year | J13: 45547 | K13: 46277 | L13: TRUE
A14: 45548 | B14: IMM005 | C14: IMM005-21919 | D14: WFE Immelman | E14: Admiral Island | F14: Trusc Fibre | G14: 229 | H14: 0 | I14: 2 year | J14: 45072 | K14: 45803 | L14: TRUE
A15: 45548 | B15: IMP001 | C15: IMP001-16736 | D15: Impinda Investments 27 CC | E15: Melkboom | F15: Trusc Wireless | G15: N/A on ISPman | H15: 0 | I15: 2 year | J15: 45467 | K15: 46197 | L15: FALSE
A16: 45548 | B16: IMV002 | C16: IMV002-27148 | D16: Imvusa Trading 546 CC | E16: Melkboom | F16: Trusc Wireless | G16: 449 | H16: 35 | I16: 2 year | J16: 45467 | K16: 46197 | L16: TRUE
A17: 45548 | B17: INC001 | C17: N/A | D17: Incorporated Beauty | G17: N/A on ISPman | H17: - | I17: 1 Year | J17: 43378 | K17: 43743 | L17: TRUE
A18: 45548 | B18: IND002 | C18: IND002-11240 | D18: Indo Trust | E18: elandshotel | F18: Trusc Wireless | G18: 799 | H18: 0 | I18: 2 year | J18: 45439 | K18: 45804 | L18: TRUE
A19: 45548 | B19: IND004 | C19: IND004-22498 | D19: Indian Princess Pty Ltd | E19: octotel_cbd-vredehoek | F19: Octotel | G19: 2874 | H19: 0 | I19: 2 year | J19: 45037 | K19: 45768 | L19: TRUE
A20: 45548 | B20: IND005 | C20: IND005-28192 | D20: Indiscape CC | E20: Admiral Island | F20: Trusc Fibre | G20: 629 | H20: 0 | I20: 2 year | J20: 45546 | K20: 46276 | L20: TRUE
A21: 45548 | B21: ING002 | C21: ING002-25097 | D21: Ingodwe Trust | E21: Dwarskersbos S/C | F21: Trusc Fibre | G21: 399 | H21: 0 | I21: 2 year | J21: 45337 | K21: 46068 | L21: TRUE
A22: 45548 | B22: INK001 | C22: INK001-19303 | D22: D Inkeld | E22: kabiscouw | F22: Trusc Wireless | G22: 349 | H22: 0 | I22: 2 year | J22: 45492 | K22: 46222 | L22: TRUE
A23: 45548 | B23: INN002 | C23: INN002-12548 | D23: Innovative Recruitment | E23: Jacobsbaai | F23: Trusc Wireless | G23: 689 | H23: 0 | I23: 2 year | J23: 44252 | K23: 44982 | L23: TRUE
A24: 45548 | B24: INT003 | C24: INT003-12832 | D24: Intellego Wines Pty Ltd | E24: Paardeberg | F24: Trusc Wireless | G24: 1149 | H24: 0 | I24: 2 year | J24: 44280 | K24: 45010 | L24: TRUE
A25: 45548 | B25: INT003 | C25: INT003-12837 | D25: Intellego Wines Pty Ltd | E25: Paardeberg | F25: Trusc Wireless | G25: 689 | H25: 0 | I25: 2 year | J25: 44281 | K25: 45011 | L25: TRUE
A26: 45548 | B26: INT004 | C26: INT004-19609 | D26: Intergro Technologies PTY LTD | E26: Veldrift S/C | F26: Trusc Fibre | G26: 649 | H26: 0 | I26: 1 Year | J26: 45189 | K26: 45555 | L26: TRUE
A27: 45548 | B27: INT005 | C27: INT005-25256 | D27: Interworks Wireless Solutions | E27: vlan59 | F27: Trusc Wireless | G27: 5499 | H27: 0 | I27: 2 year | J27: 45282 | K27: 46013 | L27: TRUE
A28: 45548 | B28: INT005 | C28: INT005-25257 | D28: Interworks Wireless Solutions | E28: vlan20_maanberg | F28: Trusc Wireless | G28: 1149 | H28: 0 | I28: 2 year | J28: 45337 | K28: 46068 | L28: TRUE
A29: 45548 | B29: IOB001 | C29: IOB001-24542 | D29: Iobase Software and Applications | E29: Admiral Island | F29: Trusc Fibre | G29: 399 | H29: 0 | I29: 2 year | J29: 45294 | K29: 46025 | L29: TRUE
... A66: 45553 | B66: ISO001 | C66: ISO001-24801 | D66: ISOQAR Africa PTY Ltd | E66: Veldrift S/C | F66: Trusc Fibre | G66: 399 | H66: 0 | I66: 2 year | J66: 45315 | K66: 46046 | L66: TRUE
A67: 45553 | B67: ISS001 | C67: ISS001-18542 | D67: VA Issel | E67: Aasvoelkop SC | F67: Trusc Fibre | G67: 0 | H67: 0 | I67: 2 year | L67: TRUE
A68: 45553 | B68: ISS001 | C68: ISS001-20134 | D68: VA Issel | E68: Tallie Marine | F68: Trusc Wireless | G68: 574 | H68: 0 | I68: 2 year | J68: 44835 | K68: 45566 | L68: TRUE
A69: 45553 | B69: ISS001 | C69: ISS001-3449 | D69: VA Issel | E69: vredex-apa5 | F69: Trusc Wireless | G69: 689 | H69: 0 | I69: 2 year | J69: 44129 | K69: 44617 | L69: TRUE | M69: Has to be removed still
A70: 45553 | B70: IVE001 | C70: IVE001-20532 | D70: TC Ives | E70: Admiral Island | F70: Trusc Fibre | G70: 689 | H70: 0 | I70: 2 year | J70: 45104 | K70: 45835 | L70: TRUE
A71: 45553 | B71: IZA001 | C71: IZA001-2671 | D71: J Izaaks | E71: Lutzville | F71: Trusc Wireless | G71: 528 | H71: 0 | I71: 2 year | J71: 42542 | K71: 43272 | L71: TRUE
A72: 45553 | B72: IZA002 | C72: IZA002-3530 | D72: CA Izaks | E72: vredenburg1-apa4 | F72: Trusc Wireless | G72: 459 | H72: 0 | I72: 2 year | J72: 44931 | K72: 45662 | L72: TRUE
A73: 45553 | B73: IZA003 | C73: IZA003-6253 | D73: AJ Izaks | E73: Vdal North | F73: Trusc Wireless | G73: 599 | H73: 0 | I73: 2 year | J73: 45518 | K73: 46248 | L73: TRUE
A74: 45553 | B74: IZA004 | C74: IZA004-7972 | D74: CR Izaks | E74: Melkboom | F74: Trusc Wireless | G74: 350 | H74: 35 | I74: 2 year | J74: 43781 | K74: 44512 | L74: TRUE
A75: 45553 | B75: IZA005 | C75: IZA005-8311 | D75: JJA Izaks | E75: Vdal North | F75: Trusc Wireless | G75: 350 | H75: 35 | I75: 2 year | J75: 43809 | K75: 44540 | L75: TRUE
A76: 45553 | B76: IZA006 | C76: IZA006-9643 | D76: MD Izaks | E76: Klawer-Res | F76: Trusc Wireless | G76: 449 | H76: 35 | I76: 2 year | J76: 45432 | K76: 46162 | L76: TRUE
...

Sheet Clients (M - P)
B1: =COUNTA(B4:B2153) -> 2150 | C1: =COUNTIF(C4:C2153,"?*") -> 1239
A2: Date | B2: Client Account | C2: Client Reference | D2: Client name | E2: Highsite / SC | F2: Type | G2: ISPMan Premium | H2: ISPMan EFT Fee | I2: Contract Duration | J2: Install Date | K2: Contract Expiry | L2: Have Contract
B3: ABC001 | C3: ABC001-12345 | D3: Mr Joe Soap | E3: Dwarskersbos S/C | F3: Trusc Wireless | I3: 1 Year | K3: 45626 | L3: TRUE | M3: Example line
A4: 45545 | B4: MAA002 | C4: MAA002-1019 | D4: GM Maas | E4: heeren-apa | F4: Trusc Wireless | G4: 229 | H4: 0 | I4: 2 year | J4: 43567 | K4: 45394 | L4: TRUE
A5: 45545 | B5: MAA004 | C5: MAA004-2885 | D5: GJJ Maass | E5: AP10039 | F5: Trusc Wireless | G5: 350 | H5: 0 | I5: 2 year | J5: 45232 | K5: 45963 | L5: TRUE
A6: 45545 | B6: MAA007 | C6: MAA007-4511 | D6: ER Maarman | E6: Klawer | F6: Trusc Wireless | G6: 350 | H6: 0 | I6: 2 year | J6: 45257 | K6: 45988 | L6: TRUE
A7: 45545 | B7: MAA008 | C7: MAA008-5096 | D7: K Maarman | E7: Lambertsbay | F7: Trusc Wireless | G7: 402 | H7: 0 | I7: 2 year | J7: 43742 | K7: 44473 | L7: TRUE
A8: 45545 | B8: MAA009 | C8: MAA009-5411 | D8: FG Maass | E8: Klawer | F8: Trusc Wireless | G8: 689 | H8: 0 | I8: 2 year | J8: 45024 | K8: 45024 | L8: TRUE
A9: 45545 | B9: MAA015 | C9: MAA015-7711 | D9: GS Maarman | E9: Lutzville | F9: Trusc Wireless | G9: 574 | H9: 0 | I9: 2 year | J9: 44618 | K9: 45348 | L9: TRUE
A10: 45545 | B10: MAA017 | C10: MAA017-8406 | D10: MM Maasdorp | E10: Lutzville | F10: Trusc Wireless | G10: 574 | H10: 0 | J10: 44608 | K10: 45338 | L10: FALSE
A11: 45545 | B11: MAA021 | C11: MAA021-18225 | D11: AJ Maasdorp | E11: Vredendal-exchange-vredex-acc-switch2 | F11: Trusc Fibre | G11: 574 | H11: 0 | I11: 2 year | J11: 45023 | K11: 45754 | L11: TRUE
A12: 45545 | B12: MAA026 | C12: MAA026-17576 | D12: P Maarman | E12: octotel_moorreesburg | F12: Octotel | G12: 804 | H12: 0 | I12: 1 Year | J12: 44601 | K12: 44966 | L12: TRUE
A13: 45545 | B13: MAA028 | C13: MAA028-11576 | D13: V Maass | E13: Olifantskop | F13: Trusc Wireless | G13: 344 | H13: 0 | I13: 2 year | J13: 44177 | K13: 45638 | L13: TRUE
A14: 45545 | B14: MAA028 | C14: MAA028-14245 | D14: V Maass | E14: Aasvoelkop-aasvoelkop-switch1 | F14: Frogfoot | G14: 1092 | H14: 0 | I14: 1 Year | J14: 44414 | K14: 44779 | L14: TRUE
A15: 45545 | B15: MAA032 | C15: MAA032-25561 | D15: D Maarman | E15: malms_gh-apa5 | F15: Trusc Wireless | G15: 350 | H15: 35 | I15: 2 year | J15: 45349 | K15: 46080 | L15: TRUE
A16: 45545 | B16: MAA035 | C16: MAA035-13601 | D16: AJH Maasdorp | E16: Okiep | F16: Trusc Wireless | G16: 574.5 | H16: 0 | I16: 2 year | J16: 45071 | K16: 45802 | L16: TRUE
A17: 45545 | B17: MAA037 | C17: MAA037-13667 | D17: W Maasdorp | E17: vdal_res-apa8 | F17: Trusc Wireless | G17: 574 | H17: 0 | I17: 2 year | J17: 44357 | K17: 45087 | L17: TRUE
A18: 45545 | B18: MAA038 | C18: MAA038-13918 | D18: S Maass | E18: vdal_north-apa1 | F18: Trusc Wireless | G18: 172 | H18: 0 | I18: 2 year | J18: 44382 | K18: 45112 | L18: TRUE
A19: 45546 | B19: MAA042 | C19: MAA042-14090 | D19: EM Maarman | E19: vdal_res-apa16 | F19: Trusc Wireless | G19: 399 | H19: 0 | I19: 2 year | J19: 45504 | K19: 46234 | L19: TRUE
A20: 45546 | B20: MAA044 | C20: MAA044-14271 | D20: W Maarman | E20: vlan10_graafwater-apa1 | F20: Trusc Wireless | G20: 250 | H20: 0 | I20: 2 year | J20: 45316 | K20: 46047 | L20: TRUE
A21: 45546 | B21: MAA046 | C21: MAA046-14594 | D21: JN Maarman | E21: Koekenaap | F21: Trusc Wireless | G21: 250 | H21: 0 | I21: 2 year | J21: 45186 | K21: 45917 | L21: TRUE
A22: 45546 | B22: MAA046 | C22: MAA046-26595 | D22: JN Maarman | E22: bitterfontein-apa4 | F22: Trusc Wireless | G22: 250 | H22: 0 | I22: 2 year | J22: 45411 | K22: 46141 | L22: TRUE
... A35: 45547 | B35: MAA066 | C35: MAA066-17304 | D35: CD Maarman | E35: kalbaskraal-apa1 | F35: Trusc Wireless | G35: 574 | H35: 0 | I35: 2 year | J35: 44572 | K35: 45302 | L35: TRUE
A36: 45547 | B36: MAA067 | C36: MAA067-17677 | D36: JL Maarman | E36: Vdal_res | F36: Trusc Wireless | G36: 574 | H36: 0 | I36: 2 year | J36: 28 Okt 2022 | K36: 28 Okt 2024 | L36: TRUE
A37: 45547 | B37: MAA068 | C37: MAA068-17808 | D37: J Maarman | E37: vlan10_graafwater-apa1 | F37: Trusc Wireless | G37: 574 | H37: 0 | I37: 2 year | J37: 44602 | K37: 45332 | L37: TRUE
A38: 45547 | B38: MAA070 | C38: MAA070-18094 | D38: LH Maarman | E38: vlan110 - paardeberg_apa11 | F38: Trusc Wireless | G38: 689 | H38: 0 | I38: 2 year | J38: 44890 | K38: 45621 | L38: TRUE
A39: 45547 | B39: MAA071 | C39: MAA071-18120 | D39: G Maarman | E39: Oranjefontein | F39: Trusc Wireless | G39: 299 | H39: 0 | I39: 2 year | J39: 45359 | K39: 46089 | L39: TRUE
A40: 45547 | B40: MAA073 | C40: MAA073-18867 | D40: A Maarman | E40: springbok2-apa20 | F40: Trusc Wireless | G40: 574 | H40: 0 | I40: 2 year | J40: 44700 | K40: 45431 | L40: TRUE
A41: 45547 | B41: MAA075 | C41: MAA075-19194 | D41: LJ Maarman | E41: Maskam | F41: Trusc Wireless | G41: 689 | H41: 0 | I41: 2 year | J41: 44734 | K41: 45465 | L41: TRUE
A42: 45547 | B42: MAA076 | C42: MAA076-19779 | D42: PJ Maarman | E42: eben-apa4 | F42: Trusc Wireless | G42: 459 | H42: 0 | I42: 2 year | J42: 44781 | K42: 45512 | L42: TRUE
A43: 45547 | B43: MAA077 | C43: MAA077-26455 | D43: ZC Maarman | E43: boberg-apa2 | F43: Trusc Wireless | G43: 350 | H43: 0 | I43: 2 year | J43: 45455 | K43: 45455 | L43: TRUE
A44: 45548 | B44: MAA078 | C44: MAA078-19988 | D44: FC Maarman | E44: Springbok 1 | F44: Trusc Wireless | G44: 574 | H44: 0 | I44: 2 year | J44: 44805 | K44: 45536 | L44: TRUE
A45: 45548 | B45: MAA079 | C45: MAA079-20602 | D45: M Maartens | E45: Dwarskersbos S/C | F45: Trusc Fibre | G45: 459 | H45: 0 | I45: 2 year | J45: 20 Okt 2022 | K45: 20 Okt 2024 | L45: TRUE
A46: 45548 | B46: MAA081 | C46: MAA081-21179 | D46: VSC Maasdorp | E46: Vdal North | F46: Trusc Wireless | G46: 459 | H46: 0 | I46: 2 year | J46: 44890 | K46: 45621 | L46: TRUE
A47: 45548 | B47: MAA082 | C47: MAA082-21415 | D47: R Maarman | E47: Lambex | F47: Trusc Wireless | G47: 574 | H47: 0 | I47: 2 year | J47: 44930 | K47: 45661 | L47: TRUE
A48: 45548 | B48: MAA084 | C48: MAA084-21507 | D48: CP Maarman | E48: Sishen | F48: Trusc Wireless | G48: 459 | H48: 0 | I48: 2 year | J48: 44935 | K48: 45666 | L48: TRUE
A49: 45548 | B49: MAA086 | C49: MAA086-21808 | D49: NT Maarman | E49: boberg-apa2 | F49: Trusc Wireless | G49: 459 | H49: 0 | I49: 2 year | J49: 44959 | K49: 45690 | L49: TRUE
A50: 45548 | B50: MAA087 | C50: MAA087-21879 | D50: M Maarman | E50: Synott | F50: Trusc Wireless | G50: 459 | H50: 0 | I50: 2 year | J50: 44964 | K50: 45695 | L50: TRUE
A51: 45548 | B51: MAA088 | C51: MAA088-22162 | D51: DJ Maarman | E51: Oranjefontein | F51: Trusc Wireless | G51: 574 | H51: 0 | I51: 2 year | J51: 44987 | K51: 45718 | L51: TRUE
A52: 45548 | B52: MAA089 | C52: MAA089-22176 | D52: JH Maarman | E52: piketberg-apa13 | F52: Trusc Wireless | G52: 574 | H52: 0 | I52: 2 year | J52: 44991 | K52: 45722 | L52: TRUE
...

Sheet Clients (Q - T)
B1: =COUNTA(B4:B1977) -> 1974 | C1: =COUNTIF(C4:C1977,"?*") -> 1033
A2: Date | B2: Client Account | C2: Client Reference | D2: Client name | E2: Highsite / SC | F2: Type | G2: ISPMan Premium | H2: ISPMan EFT Fee | I2: Contract Duration | J2: Install Date | K2: Contract Expiry | L2: Have Contract
B3: ABC001 | C3: ABC001-12345 | D3: Mr Joe Soap | E3: Dwarskersbos S/C | F3: Trusc Wireless | I3: 1 Year | K3: 45626 | L3: TRUE | M3: Example line
A4: 45558 | B4: QAN001 | C4: QAN001-25743 | D4: RP Qanetsi | E4: Oranjefontein | F4: Trusc Wireless | G4: 350 | H4: 0 | I4: 2 year | J4: 45364 | K4: 46094 | L4: TRUE
A5: 45558 | B5: QHA001 | C5: QHA001-1039 | D5: Qhayisa en Richmond Pre School | E5: Vdal_res | F5: Trusc Wireless | G5: 350 | H5: 0 | I5: 2 year | J5: 1 Desember 2023 | K5: 1 Desember 2025 | L5: TRUE
A6: 45558 | B6: QHI001 | C6: QHI001-27778 | D6: BJ Qhive | E6: mekano-apa7 | F6: Trusc Wireless | G6: 399 | H6: 0 | I6: 2 year | J6: 45511 | K6: 46241 | L6: TRUE
A7: 45558 | B7: QHU001 | C7: QHU001-25093 | D7: N Qhuza | E7: vlan109_oranjefontein-ap10_C-ppp | F7: Trusc Wireless | G7: 350 | H7: 0 | I7: 2 year | J7: 45334 | K7: 45334 | L7: TRUE
A8: 45558 | B8: QOM002 | C8: QOM002-26027 | D8: SG Qomoyi | E8: kabiscouw | F8: Trusc Wireless | G8: 575 | H8: 0 | I8: 2 year | J8: 45396 | K8: 46126 | L8: TRUE
A9: 45558 | B9: QUA002 | C9: QUA002-19352 | D9: Quantum Forklifts | E9: Steelwater | F9: Trusc Wireless | G9: 1149 | H9: 0 | I9: 2 year | J9: 44743 | K9: 45474 | L9: FALSE
A10: 45558 | B10: QUA005 | C10: QUA005-20670 | D10: BA Quayle | E10: Veldrift S/C | F10: Trusc Fibre | G10: 399 | H10: 0 | I10: 2 year | J10: 45155 | K10: 45886 | L10: TRUE
A11: 45558 | B11: QUI002 | C11: QUI002-13083 | D11: CC Quill | E11: Tallie Marine | F11: Trusc Wireless | G11: 399 | H11: 0 | I11: 2 year | J11: 45517 | K11: 46247 | L11: TRUE
A12: 45558 | B12: QUI003 | C12: QUI003-19476 | D12: Quickstep 668(PTY)Ltd | E12: St Helena | F12: Trusc Wireless | G12: 574 | H12: 0 | I12: 1 Year | J12: 44774 | K12: 45139 | L12: FALSE
A13: 45558 | B13: QUI004 | C13: QUI004-19814 | D13: DD Quill | E13: Octotel_Ruyterwacht | F13: Octotel | G13: 804 | H13: 0 | I13: 1 Year | J13: 44799 | K13: 45164 | L13: FALSE
A14: 45558 | B14: QUI006 | C14: QUI006-23070 | D14: W Quickfall | E14: Nababeep | F14: Trusc Wireless | G14: 574 | H14: 0 | I14: 2 year | J14: 45115 | K14: 45846 | L14: TRUE
A15: 45558 | B15: QUN001 | C15: QUN001-24508 | D15: CY Qunya | E15: retshof | F15: Trusc Wireless | G15: 350 | H15: 0 | I15: 2 year | J15: 45270 | K15: 46001 | L15: TRUE
A16: 45558 | B16: QUP001 | C16: QUP001-17080 | D16: NV Qupe | E16: Vdal_res | F16: Trusc Wireless | G16: 344 | H16: 35 | I16: 2 year | J16: 44549 | K16: 45279 | L16: FALSE
A17: 45579 | B17: QUI007 | C17: QUI007-28333 | D17: AJ Quirinano | E17: Kalbaskraal | F17: Trusc Wireless | G17: 399 | H17: 35 | I17: 2 year | J17: 45564 | K17: 46294 | L17: TRUE
A18: 45558 | B18: RAA002 | C18: RAA002-1297 | D18: PS Raad | E18: Synott | F18: Trusc Wireless | G18: 344 | H18: 0 | I18: Month to Month | J18: 44132 | K18: 28 Oct 0222 | L18: FALSE
A19: 45558 | B19: RAA003 | C19: RAA003-2448 | D19: VE Raath | E19: Rilau | F19: Trusc Wireless | G19: 298 | H19: 0 | I19: 2 year | J19: 47295 | K19: 44373 | L19: FALSE
A20: 45558 | B20: RAA005 | C20: RAA005-5146 | D20: HJ Raage | E20: Koekenaap | F20: Trusc Wireless | G20: 0 | H20: 0 | I20: 2 year | J20: 44396 | K20: 45126 | L20: FALSE | M20: No pricing in ispman
A21: 45558 | B21: RAA005 | C21: RAA005-14536 | D21: HJ Raage | E21: Koekenaap | F21: Trusc Wireless | G21: 574 | H21: 0 | I21: 2 year | J21: 44412 | K21: 45142 | L21: FALSE
A22: 45558 | B22: RAA006 | C22: RAA006-5501 | D22: S Raad | E22: Clan | F22: Trusc Wireless | G22: 288 | I22: 2 year | J22: 44092 | K22: 44822 | L22: FALSE
A23: 45558 | B23: RAA007 | C23: RAA007-9888 | D23: ZK Raatus | E23: Koraan | F23: Trusc Wireless | G23: 459 | H23: 0 | I23: 2 year | J23: 44736 | K23: 45467 | L23: FALSE
A24: 45558 | B24: RAA012 | C24: RAA012-16269 | D24: GJ Raaths | E24: olive_place-SC | F24: Trusc Fibre | G24: 632 | H24: 0 | I24: 1 Year | J24: 44525 | K24: 45255 | L24: FALSE
A25: 45558 | B25: RAB008 | C25: RAB008-26170 | D25: CJ Martin | E25: Vdal North | F25: Trusc Wireless | G25: 350 | H25: 0 | I25: 2 year | J25: 45410 | K25: 46140 | L25: TRUE
A26: 45558 | B26: RAB009 | C26: RAB009-17076 | D26: J Rabie | E26: Goudmyn | F26: Trusc Wireless | G26: 350 | H26: 35 | I26: 2 year | J26: 45399 | K26: 46129 | L26: TRUE
A27: 45558 | B27: RAB010 | C27: RAB010-17208 | D27: AA Rabe | E27: Goudmyn | F27: Trusc Wireless | G27: 350 | H27: 0 | I27: 1 Year | J27: 45281 | K27: 45647 | L27: TRUE
A28: 45558 | B28: RAB012 | C28: RAB012-25314 | D28: C Rabie | E28: lm_bakwerke | F28: Trusc Wireless | G28: 350 | H28: 0 | I28: 2 year | J28: 45336 | K28: 46067 | L28: TRUE
A29: 45558 | B29: RAB013 | C29: RAB013-26845 | D29: ES Rabe | E29: Klipberg | F29: Trusc Wireless | G29: 449 | H29: 0 | I29: 2 year | J29: 45438 | K29: 46168 | L29: TRUE
A30: 45558 | B30: RAC001 | C30: RAC001-3767 | D30: SP Rack | E30: Laaiplek | F30: Trusc Fibre | G30: 1149 | H30: 0 | I30: 2 year | J30: 44616 | K30: 45346 | L30: FALSE
A31: 45558 | B31: RAD007 | C31: RAD007-14606 | D31: AF Rademeyer | E31: Bitterfontein | F31: Trusc Wireless | G31: 977 | H31: 0 | I31: 2 year | J31: 44538 | K31: 45268 | L31: FALSE
A32: 45558 | B32: RAD008 | C32: RAD008-14690 | D32: D Radloff | E32: Vdal North | F32: Trusc Wireless | G32: 459 | H32: 0 | I32: 2 year | J32: 44427 | K32: 45157 | L32: FALSE
A33: 45558 | B33: RAD009 | C33: RAD009-15087 | D33: J Radyn | E33: Blouwater | F33: Trusc Wireless | G33: 804 | H33: 0 | I33: 2 year | J33: 44447 | K33: 45177 | L33: FALSE
A34: 45558 | B34: RAD011 | C34: RAD011-17945 | D34: TN Radebe | E34: Voorberg | F34: Trusc Wireless | G34: 804 | H34: 0 | I34: 2 year | J34: 44622 | K34: 45353 | L34: FALSE
... A60: 45560 | B60: RAS011 | C60: RAS011-25775 | D60: JM Ras | E60: lag-21:115.1280196.43.47.2 | F60: Openserve | G60: 699 | H60: 0 | I60: 2 year | J60: 45370 | K60: 46100 | L60: TRUE
A61: 45560 | B61: RAU003 | C61: RAU003-4773 | D61: JN Raubenheimer | E61: lutzkerk-apa3 | F61: Trusc Wireless | G61: 804 | H61: 0 | I61: 2 year | J61: 45359 | K61: 0/03/2026 | L61: TRUE
A62: 45560 | B62: RAU005 | C62: RAU005-26723 | D62: IG Rautenbach | E62: Piketberg | F62: Openserve | G62: 699 | H62: 0 | I62: 1 Year | J62: 45452 | K62: 46182 | L62: TRUE
A63: 45560 | B63: RAU008 | C63: RAU008-20098 | D63: CV Rauch | E63: Paardeberg | F63: Trusc Wireless | G63: 689 | H63: 0 | I63: 2 year | J63: 44820 | K63: 45551 | L63: TRUE
A64: 45560 | B64: RAU009 | C64: RAU009-27096 | D64: R Rautenbach | E64: Nivica | F64: Trusc Fibre | G64: 499 | H64: 0 | I64: 1 Year | J64: 45456 | K64: 45821 | L64: TRUE
A65: 45560 | B65: RAY003 | C65: RAY003-15896 | D65: BK Raymond | E65: Okiep | F65: Trusc Wireless | G65: 399 | H65: 0 | I65: 2 Year | J65: 45477 | K65: 46207 | L65: TRUE
...

Sheet Clients (U - V)
B1: =COUNTA(B4:B1104) -> 1101 | C1: =COUNTIF(C4:C1104,"?*") -> 117
A2: Date | B2: Client Account | C2: Client Reference | D2: Client name | E2: Highsite / SC | F2: Type | G2: ISPMan Premium | H2: ISPMan EFT Fee | I2: Contract Duration | J2: Install Date | K2: Contract Expiry | L2: Have Contract
B3: ABC001 | C3: ABC001-12345 | D3: Mr Joe Soap | E3: Dwarskersbos S/C | F3: Trusc Wireless | I3: 1 Year | K3: 45626 | L3: TRUE | M3: Example line
A4: 45548 | B4: UDD001 | C4: UDD001-14796 | D4: J Uddin | E4: Nababeep | F4: Trusc Wireless | G4: 350 | H4: 0 | I4: 2 year | J4: 45338 | K4: 46069 | L4: TRUE
A5: 45548 | B5: UDD001 | C5: UDD001-25436 | D5: J Uddin | E5: Nababeep | F5: Trusc Wireless | G5: 350 | H5: 0 | I5: 2 year | J5: 45343 | K5: 46074 | L5: TRUE
A6: 45548 | B6: UDD003 | C6: UDD003-27636 | D6: M Uddin | E6: Okiep | F6: Trusc Wireless | G6: 299 | H6: 0 | I6: 2 year | J6: 45524 | K6: 46254 | L6: TRUE
A7: 45548 | B7: UIL001 | C7: UIL001-6618 | D7: Uilenkraal Pty Ltd | E7: Klipberg | F7: Trusc Wireless | G7: 689 | H7: 0 | I7: 2 year | J7: 43572 | K7: 44303 | L7: TRUE
A8: 45548 | B8: UIL001 | C8: UIL001-6632 | D8: Uilenkraal Pty Ltd | E8: Klipberg | F8: Trusc Wireless | G8: 1207 | H8: 0 | I8: 2 year | J8: 43629 | K8: 44360 | L8: TRUE
A9: 45548 | B9: UIL002 | C9: UIL002-24726 | D9: Uilenkraal Pty Ltd | E9: koringberg | F9: Trusc Wireless | G9: 350 | H9: 0 | I9: 2 year | J9: 45284 | K9: 45650 | L9: TRUE
A10: 45548 | B10: UIT004 | C10: UIT004-11046 | D10: Uitkyk Boerdery | E10: klipberg | F10: Trusc Wireless | G10: 804 | H10: 0 | I10: 2 year | J10: 44862 | K10: 45593 | L10: TRUE
A11: 45548 | B11: ULT001 | C11: ULT001-10437 | D11: 3 Ts Media Pty Ltd ta Ultimate Media | E11: koringberg | F11: Trusc Wireless | G11: 804 | H11: 0 | I11: 2 year | J11: 44778 | K11: 45509 | L11: TRUE
A12: 45548 | B12: UMA001 | C12: UMA001-13237 | D12: A Umans | E12: sh (saldanha Heights) | F12: Trusc Wireless | G12: 574 | H12: 0 | I12: 2 year | J12: 44320 | K12: 45050 | L12: TRUE
A13: 45548 | B13: UMA002 | C13: UMA002-17601 | D13: Marlene Umans | E13: deklip | F13: Trusc Wireless | G13: 449 | H13: 0 | I13: 2 year | J13: 45429 | K13: 46159 | L13: TRUE
A14: 45548 | B14: UMO001 | C14: UMO001-3900 | D14: Umoya Energy (RF)(PTY) LTD | E14: vlan200_umoya-fibre-ppp | F14: Trusc Wireless | G14: 11250.04 | H14: 0 | I14: Corporate Billing | L14: TRUE
A15: 45548 | B15: UMZ001 | C15: UMZ001-3617 | D15: Umzamani Fishing cc | E15: None | F15: Trusc Wireless | G15: 816 | H15: 0 | I15: 2 year | J15: 42846 | K15: 43576 | L15: TRUE
A16: 45548 | B16: UND001 | C16: UND001-26871 | D16: CCG Underwood | E16: None | F16: Trusc Fibre | G16: 499 | H16: 0 | I16: 2 year | J16: 45445 | K16: 46175 | L16: TRUE
A17: 45548 | B17: UNE001 | C17: UNE001-658 | D17: Uniekum Contracting PTY LTD | E17: leipoldtvillepop | F17: Trusc Wireless | G17: 344 | H17: 35 | I17: 2 year | J17: 44998 | K17: 45729 | L17: TRUE
A18: 45548 | B18: UNG001 | C18: UNG001-26415 | D18: M Ungerer | E18: None | F18: Trusc Fibre | G18: 399 | H18: 0 | I18: 2 year | J18: 45409 | K18: 46139 | L18: TRUE
A19: 45548 | B19: UNI005 | C19: UNI005-4801 | D19: UNI-SERV DPC Pty Ltd | E19: Masada | F19: Trusc Wireless | G19: 632 | H19: 0 | I19: 2 year | J19: 43134 | K19: 43864 | L19: TRUE
A20: 45548 | B20: UNI006 | C20: UNI006-15043 | D20: Unik Group of Companies (Pty) Ltd | E20: None | F20: Openserve | G20: 1375 | H20: 0 | I20: 2 year | J20: 44469 | K20: 45199 | L20: TRUE
A21: 45548 | B21: UNI007 | C21: UNI007-8615 | D21: Unifrutti SA (Pty) Ltd | E21: tafelberg | F21: Trusc Wireless | G21: 7474 | H21: 0 | I21: 2 year | J21: 44974 | K21: 45705 | L21: TRUE
A22: 45548 | B22: UNI008 | C22: UNI008-10034 | D22: Unique Premium Beverages | E22: retshof | F22: Trusc Wireless | G22: 599 | H22: 35 | I22: 2 year | J22: 45505 | K22: 46235 | L22: TRUE
A23: 45548 | B23: UNI009 | C23: UNI009-15407 | D23: Uniting Reformed Church | E23: deklip | F23: Trusc Wireless | G23: 350 | H23: 0 | I23: 2 year | J23: 45626 | K23: 46356 | L23: TRUE
A24: 45548 | B24: UPT007 | C24: UPT007-21509 | D24: A Upton | E24: vlan130-koraan | F24: Trusc Wireless | G24: 344 | H24: 0 | I24: 2 year | J24: 44933 | K24: 45664 | L24: TRUE
A25: 45548 | B25: URB003 | C25: URB003-27146 | D25: Urban Eye Planning and Development Pty Ltd | E25: Tallie Marine | F25: Trusc Wireless | G25: 799 | H25: 0 | I25: 2 year | J25: 45463 | K25: 46193 | L25: TRUE
A26: 45548 | B26: URI001 | C26: URI001-2485 | D26: Urionskraal Boerdery | E26: vlan3236_URI001-2485-SpecialLink | F26: Trusc Wireless | G26: 459 | H26: 0 | I26: 2 year | J26: 43725 | K26: 44456 | L26: TRUE
... A28: 45548 | B28: UYS004 | C28: UYS004-7480 | D28: S Uys | E28: De Hoek | F28: Trusc Wireless | G28: 350 | H28: 0 | I28: 2 year | J28: 45282 | K28: 46013 | L28: TRUE
A29: 45548 | B29: UYS005 | C29: UYS005-8853 | D29: SM Uys | L29: FALSE
A30: 45548 | B30: UYS007 | C30: UYS007-9950 | D30: E Uys | E30: ether1 - sh | F30: Trusc Wireless | G30: 804 | H30: 0 | I30: 2 year | J30: 44827 | K30: 45558 | L30: TRUE
A31: 45548 | B31: UYS008 | C31: UYS008-10355 | D31: JG Uys | E31: goudmyn | F31: Trusc Wireless | G31: 230 | H31: 0 | I31: 2 year | J31: 44009 | K31: 44739 | L31: TRUE
A32: 45548 | B32: UYS009 | C32: UYS009-13102 | D32: M Uys | E32: olive_place-SC | F32: Trusc Fibre | G32: 399 | H32: 0 | I32: 1 Year | J32: 45441 | K32: 46171 | L32: TRUE
A33: 45574 | B33: UYS013 | C33: UYS013-25598 | D33: S Uys | E33: goudmyn | F33: Trusc Wireless | G33: 350 | H33: 0 | I33: 2 year | J33: 45352 | K33: 46082 | L33: TRUE
A34: 45574 | B34: VAA006 | C34: VAA006-19070 | D34: PJ Vaas | E34: Vdal_res | F34: Trusc Wireless | G34: 349 | H34: 0 | I34: 2 year | J34: 45475 | K34: 46205 | L34: TRUE
A35: 45574 | B35: VAA008 | C35: VAA008-24585 | D35: Vaalvlei Boerdery Pty Ltd | E35: Strand | F35: Trusc Wireless | G35: 250 | H35: 0 | I35: 2 year | J35: 45273 | K35: 46004 | L35: TRUE
A36: 45574 | B36: VAL001 | C36: VAL001-804 | D36: LP Valentine | E36: Spioenkop | F36: Trusc Wireless | G36: 1552 | H36: 0 | I36: 2 year | J36: 43630 | K36: 44361 | L36: TRUE
A37: 45574 | B37: VAL002 | C37: VAL002-1774 | D37: GAH Traveho PTY LTD | E37: langebaan | F37: Trusc Wireless | G37: 673 | H37: 0 | I37: 2 year | J37: 44665 | K37: 45396 | L37: TRUE
A38: 45574 | B38: VAL006 | C38: VAL006-5487 | D38: Valskuil Boerdery | E38: paleis-apa2 | F38: Trusc Wireless | G38: 804 | H38: 35 | I38: 2 year | J38: 44833 | K38: 45564 | L38: TRUE
A39: 45574 | B39: VAL008 | C39: VAL008-7976 | D39: B Vallentyn | E39: Modderfontein | F39: Trusc Wireless | G39: 574 | H39: 0 | I39: 2 year | J39: 44480 | K39: 45210 | L39: TRUE
A40: 45574 | B40: VAL010 | C40: VAL010-10044 | D40: NP Valentyn | E40: Maskam | F40: Trusc Wireless | G40: 350 | H40: 0 | I40: 2 year | J40: 45288 | K40: 46019 | L40: TRUE
A41: 45574 | B41: VAL011 | C41: VAL011-23714 | D41: J Valentyn | E41: Koringberg | F41: Trusc Wireless | G41: 350 | H41: 0 | I41: 2 year | J41: 45204 | K41: 45935 | L41: TRUE
...

Sheet Clients (W - Z)
B1: =COUNTA(B4:B559) -> 556 | C1: =COUNTIF(C4:C559,"?*") -> 378
A2: Date | B2: Client Account | C2: Client Reference | D2: Client name | E2: Highsite / SC | F2: Type | G2: ISPMan Premium | H2: ISPMan EFT Fee | I2: Contract Duration | J2: Install Date | K2: Contract Expiry | L2: Have Contract
B3: ABC001 | C3: ABC001-12345 | D3: Mr Joe Soap | E3: Dwarskersbos S/C | F3: Trusc Wireless | I3: 1 Year | K3: 45626 | L3: TRUE | M3: Example line
A4: 45548 | B4: WAA001 | C4: WAA001-10016 | D4: A Waanar | E4: Voorberg | F4: Trusc Wireless | G4: 574 | H4: 0 | I4: 2 year | J4: 43987 | K4: 44717 | L4: TRUE
A5: 45548 | B5: WAA002 | C5: WAA002-17293 | D5: Waaidraai Boerdery | E5: Sishen | F5: Trusc Wireless | G5: 250 | H5: 0 | I5: 2 year | J5: 45295 | K5: 45661 | L5: TRUE
A6: 45548 | B6: WAD001 | C6: WAD001-23014 | D6: Wadrif Aartappels PTY LTD | E6: Spioenkop | F6: Trusc Wireless | G6: 976 | H6: 0 | L6: FALSE
A7: 45548 | B7: WAG004 | C7: WAG004-11574 | D7: G Wagner | E7: Heuningberg | F7: Trusc Wireless | G7: 574 | H7: 35 | I7: 2 year | J7: 44968 | K7: 45699 | L7: TRUE
A8: 45548 | B8: WAG005 | C8: WAG005-11795 | D8: SM Wagner | E8: Graafwater | F8: Trusc Wireless | G8: 350 | H8: 0 | I8: 2 year | J8: 45275 | K8: 46006 | L8: TRUE
A9: 45548 | B9: WAG008 | C9: WAG008-28075 | D9: AA Wagenstroom | E9: Graafwater | F9: Trusc Wireless | G9: 399 | H9: 0 | I9: 2 year | J9: 45548 | K9: 46278 | L9: TRUE
A10: 45548 | B10: WAG009 | C10: WAG009-15832 | D10: SC Wagemans | E10: Aasvoelkop SC | F10: Openserve | G10: 972 | H10: 0 | I10: 1 Year | J10: 44516 | K10: 44881 | L10: FALSE
A11: 45548 | B11: WAG010 | C11: WAG010-17217 | D11: LK Wagenaar | E11: Klawer | F11: Trusc Wireless | G11: 350 | H11: 0 | I11: 2 year | J11: 45283 | K11: 46017 | L11: TRUE
A12: 45548 | B12: WAG011 | C12: WAG011-20222 | D12: JS Wagener | E12: Admiral Island | F12: Trusc Fibre | G12: 599 | H12: 0 | I12: 2 year | J12: 44957 | K12: 45688 | L12: TRUE
A13: 45548 | B13: WAG013 | C13: WAG013-22512 | D13: PJ Wagner | E13: Klawer | F13: Trusc Wireless | G13: 574 | H13: 0 | I13: 2 year | J13: 45052 | K13: 45783 | L13: TRUE
A14: 45548 | B14: WAG014 | C14: WAG014-23557 | D14: THJ Wagenstroom | E14: Heuningberg | F14: Trusc Wireless | G14: 385 | H14: 0 | I14: 2 year | J14: 45188 | K14: 45919 | L14: TRUE
A15: 45548 | B15: WAG015 | C15: WAG015-25528 | D15: FJ Wagenaar | E15: klipberg | F15: Trusc Wireless | G15: 350 | H15: 0 | I15: 2 year | J15: 45351 | K15: 29 Feb 2026 | L15: FALSE
A16: 45548 | B16: WAG016 | C16: WAG016-25554 | D16: L Wagenaar | E16: Kalbaskraal | F16: Trusc Wireless | G16: 385 | H16: 0 | I16: 2 year | J16: 45361 | K16: 46091 | L16: TRUE
A17: 45548 | B17: WAG017 | C17: WAG017-26948 | D17: M Wagener | E17: Strand | F17: Trusc Wireless | G17: 649 | H17: 0 | I17: 2 year | J17: 45463 | K17: 46193 | L17: TRUE
A18: 45548 | B18: WAG018 | C18: WAG018-27563 | D18: CG Wagener | E18: Lambertsbay | F18: Trusc Wireless | G18: 348 | H18: 35 | I18: 2 year | J18: 45505 | K18: 46235 | L18: TRUE
A19: 45555 | B19: WAH001 | C19: WAH001-3267 | D19: K Wahl | E19: langebaan | F19: Trusc Wireless | G19: 574 | H19: 0 | I19: 2 year | J19: 44061 | K19: 44791 | L19: TRUE
A20: 45555 | B20: WAI001 | C20: WAI001-23403 | D20: MMM Waily | E20: Dwarskersbos S/C | F20: Trusc Fibre | G20: 399 | H20: 0 | I20: 2 year | J20: 45232 | K20: 45963 | L20: TRUE
A21: 45548 | B21: WAI002 | C21: WAI002-22880 | D21: The Waitrose Foundation | E21: vlan20_maanberg | F21: Trusc Wireless | G21: 574 | H21: 0 | I21: 2 year | J21: 45133 | K21: 45864 | L21: TRUE
A22: 45548 | B22: WAI002 | C22: WAI002-22932 | D22: The Waitrose Foundation | E22: grootfontein | F22: Trusc Wireless | G22: 574 | H22: 0 | I22: 2 year | J22: 45134 | K22: 45865 | L22: TRUE
A23: 45548 | B23: WAI002 | C23: WAI002-23032 | D23: The Waitrose Foundation | E23: Steelwater | F23: Trusc Wireless | G23: 574 | H23: 0 | I23: 2 year | J23: 45128 | K23: 45859 | L23: TRUE
A24: 45548 | B24: WAI002 | C24: WAI002-23474 | D24: The Waitrose Foundation | E24: moutons | F24: Trusc Wireless | G24: 576 | H24: 0 | I24: 2 year | J24: 45192 | K24: 45923 | L24: TRUE
A25: 45548 | B25: WAK001 | C25: WAK001-10079 | D25: AJ Wakefield | E25: Doornbaai | F25: Trusc Wireless | G25: 344 | H25: 35 | I25: 2 year | J25: 45080 | K25: 45811 | L25: TRUE
A26: 45548 | B26: WAK002 | C26: WAK002-27529 | D26: F Wakens | E26: Koringberg | F26: Trusc Wireless | G26: 399 | H26: 0 | I26: 2 year | J26: 45546 | K26: 46276 | L26: TRUE
A27: 45548 | B27: WAL001 | C27: WAL001-1647 | D27: MDM Walters | E27: lang | F27: Trusc Wireless | G27: 459 | H27: 0 | I27: 2 year | J27: 44845 | K27: 45576 | L27: TRUE
... A30: 45555 | B30: WAL010 | C30: WAL010-5556 | D30: ZM Walkers | E30: wt | F30: Trusc Wireless | G30: 804 | H30: 0 | I30: 2 year | J30: 44132 | K30: 44862 | L30: TRUE
A31: 45548 | B31: WAL012 | C31: WAL012-7006 | D31: JD Walker | E31: Masada | F31: Trusc Wireless | G31: 0 | H31: 0 | I31: 2 year | J31: 43608 | L31: TRUE
A32: 45548 | B32: WAL013 | C32: WAL013-9221 | D32: ZA Walters | E32: lang | F32: Trusc Wireless | G32: 229.5 | H32: 0 | I32: 2 year | J32: 44839 | K32: 45570 | L32: TRUE
A33: 45548 | B33: WAL017 | C33: WAL017-11345 | D33: OC Waldeck | E33: Oranjefontein | F33: Trusc Wireless | G33: 574 | H33: 0 | I33: 2 year | J33: 44132 | K33: 44862 | L33: TRUE
A34: 45548 | B34: WAL019 | C34: WAL019-12481 | D34: EN Walters | E34: Paardeberg | F34: Trusc Wireless | G34: 2070 | H34: 0 | I34: 2 year | J34: 44274 | K34: 45004 | L34: TRUE
A35: 45548 | B35: WAL021 | C35: WAL021-16923 | D35: SW Walker | E35: Koraan | F35: Trusc Wireless | G35: 350 | H35: 35 | I35: 2 year | J35: 45283 | K35: 46014 | L35: TRUE
A36: 45548 | B36: WAL022 | C36: WAL022-23645 | D36: K Walita | E36: Lutzville | F36: Trusc Wireless | G36: 344 | H36: 0 | I36: 2 year | J36: 45199 | K36: 45930 | L36: TRUE
A37: 45548 | B37: WAL023 | C37: WAL023-21978 | D37: SV Walaza | E37: Oranjefontein | F37: Trusc Wireless | G37: 689 | H37: 0 | I37: 2 year | J37: 44973 | K37: 45704 | L37: TRUE
A38: 45548 | B38: WAL025 | C38: WAL025-26198 | D38: JJ Waldeck | E38: saron | F38: Trusc Wireless | G38: 350 | H38: 0 | I38: 2 year | J38: 45408 | K38: 46138 | L38: TRUE
A39: 45555 | B39: WAN002 | C39: WAN002-3776 | D39: A Wanneburg | E39: Laaiplek | F39: Trusc Wireless | G39: 549 | H39: 0 | L39: FALSE
A40: 45548 | B40: WAN004 | C40: WAN004-11492 | D40: G Waneburg | E40: malms_gh | F40: Trusc Wireless | G40: 574 | H40: 0 | I40: 2 year | J40: 44152 | K40: 44882 | L40: TRUE
A41: 45548 | B41: WAR005 | C41: WAR005-6677 | D41: EA Warnich | E41: koringberg | F41: Trusc Wireless | G41: 574 | H41: 0 | I41: 2 year | J41: 43615 | K41: 43981 | L41: TRUE
A42: 45548 | B42: WAR011 | C42: WAR011-23071 | D42: E Warambwa | E42: Vredendal S/C | F42: Trusc Fibre | G42: 459 | H42: 35 | I42: 2 year | J42: 45156 | K42: 45887 | L42: FALSE
...

Sheet Data
A1: Term | B1: Highsite | C1: Type
A3: Month to Month | B3: Aasvoelkop SC | C3: Trusc Wireless
A4: 1 Year | B4: Aasvoelkop-aasvoelkop-switch1 | C4: Trusc Fibre
A5: 2 year | B5: Admiral Island | C5: Openserve
A6: Sponsorship Agreement | B6: De Hoek | C6: Octotel
A7: Current Terms | B7: deklip2 | C7: DFA
A8: Corporate Billing | B8: Biedouw | C8: Frogfoot
B9: Rooiberg | C9: Vumatel
B10: Veldrift
B11: Dwars
B12: Trusc - 10040
B13: pakhuis
B14: Openserve
B15: Wolvekop
B16: AP10030
B17: Duiwels
B18: AP10023
B19: Octotel Blouberg
B20: Vlan70
B21: wlan1
... B327: vlan20_meisies_koshuis-apa2
